Workbook

Sheet 🔍 Buscador
A2: 🔍 BUSCADOR DE INVENTARIO TI
B4: 🔎 Buscar por nombre / usuario: | G4: PIA
G5: ✏️ Escribe aquí el nombre de la persona
A7: 💻 Resultados — PC
A8: Rut | B8: Persona | C8: Fecha Entrega | D8: Estado | E8: Área | F8: Ubicación | G8: Marca | H8: Modelo | I8: Nº de Serie | J8: Doc. Firmado | K8: Mochila | L8: Cargador | M8: Entrega Informática | N8: Entrega Usuario | O8: Observaciones
A9: {=IFERROR(INDEX(_Data!A2:A111,SMALL(IF(ISNUMBER(SEARCH(IF(G4="",CHAR(1),G4),_Data!B2:B111)),ROW(_Data!B2:B111)-1),1)),"")} -> 0 | B9: {=IFERROR(INDEX(_Data!B2:B111,SMALL(IF(ISNUMBER(SEARCH(IF(G4="",CHAR(1),G4),_Data!B2:B111)),ROW(_Data!B2:B111)-1),1)),"")} -> Pia Escobar | C9: {=IFERROR(INDEX(_Data!C2:C111,SMALL(IF(ISNUMBER(SEARCH(IF(G4="",CHAR(1),G4),_Data!B2:B111)),ROW(_Data!B2:B111)-1),1)),"")} -> 05-12-2025 | D9: {=IFERROR(INDEX(_Data!D2:D111,SMALL(IF(ISNUMBER(SEARCH(IF(G4="",CHAR(1),G4),_Data!B2:B111)),ROW(_Data!B2:B111)-1),1)),"")} -> Asignado | E9: {=IFERROR(INDEX(_Data!E2:E111,SMALL(IF(ISNUMBER(SEARCH(IF(G4="",CHAR(1),G4),_Data!B2:B111)),ROW(_Data!B2:B111)-1),1)),"")} -> Auditoria | F9: {=IFERROR(INDEX(_Data!F2:F111,SMALL(IF(ISNUMBER(SEARCH(IF(G4="",CHAR(1),G4),_Data!B2:B111)),ROW(_Data!B2:B111)-1),1)),"")} -> Casa Matriz | G9: {=IFERROR(INDEX(_Data!G2:G111,SMALL(IF(ISNUMBER(SEARCH(IF(G4="",CHAR(1),G4),_Data!B2:B111)),ROW(_Data!B2:B111)-1),1)),"")} -> Lenovo | H9: {=IFERROR(INDEX(_Data!H2:H111,SMALL(IF(ISNUMBER(SEARCH(IF(G4="",CHAR(1),G4),_Data!B2:B111)),ROW(_Data!B2:B111)-1),1)),"")} -> Ideapad Slim3 | I9: {=IFERROR(INDEX(_Data!I2:I111,SMALL(IF(ISNUMBER(SEARCH(IF(G4="",CHAR(1),G4),_Data!B2:B111)),ROW(_Data!B2:B111)-1),1)),"")} -> PF4CA6ZM | J9: {=IFERROR(INDEX(_Data!J2:J111,SMALL(IF(ISNUMBER(SEARCH(IF(G4="",CHAR(1),G4),_Data!B2:B111)),ROW(_Data!B2:B111)-1),1)),"")} -> NO | K9: {=IFERROR(INDEX(_Data!K2:K111,SMALL(IF(ISNUMBER(SEARCH(IF(G4="",CHAR(1),G4),_Data!B2:B111)),ROW(_Data!B2:B111)-1),1)),"")} -> NO | L9: {=IFERROR(INDEX(_Data!L2:L111,SMALL(IF(ISNUMBER(SEARCH(IF(G4="",CHAR(1),G4),_Data!B2:B111)),ROW(_Data!B2:B111)-1),1)),"")} -> SI | M9: {=IFERROR(INDEX(_Data!M2:M111,SMALL(IF(ISNUMBER(SEARCH(IF(G4="",CHAR(1),G4),_Data!B2:B111)),ROW(_Data!B2:B111)-1),1)),"")} -> Emilio Droguett | N9: {=IFERROR(INDEX(_Data!N2:N111,SMALL(IF(ISNUMBER(SEARCH(IF(G4="",CHAR(1),G4),_Data!B2:B111)),ROW(_Data!B2:B111)-1),1)),"")} -> Pia Escobar | O9: {=IFERROR(INDEX(_Data!O2:O111,SMALL(IF(ISNUMBER(SEARCH(IF(G4="",CHAR(1),G4),_Data!B2:B111)),ROW(_Data!B2:B111)-1),1)),"")} -> 0
A10: {=IFERROR(INDEX(_Data!A2:A111,SMALL(IF(ISNUMBER(SEARCH(IF(G4="",CHAR(1),G4),_Data!B2:B111)),ROW(_Data!B2:B111)-1),2)),"")} | B10: {=IFERROR(INDEX(_Data!B2:B111,SMALL(IF(ISNUMBER(SEARCH(IF(G4="",CHAR(1),G4),_Data!B2:B111)),ROW(_Data!B2:B111)-1),2)),"")} | C10: {=IFERROR(INDEX(_Data!C2:C111,SMALL(IF(ISNUMBER(SEARCH(IF(G4="",CHAR(1),G4),_Data!B2:B111)),ROW(_Data!B2:B111)-1),2)),"")} | D10: {=IFERROR(INDEX(_Data!D2:D111,SMALL(IF(ISNUMBER(SEARCH(IF(G4="",CHAR(1),G4),_Data!B2:B111)),ROW(_Data!B2:B111)-1),2)),"")} | E10: {=IFERROR(INDEX(_Data!E2:E111,SMALL(IF(ISNUMBER(SEARCH(IF(G4="",CHAR(1),G4),_Data!B2:B111)),ROW(_Data!B2:B111)-1),2)),"")} | F10: {=IFERROR(INDEX(_Data!F2:F111,SMALL(IF(ISNUMBER(SEARCH(IF(G4="",CHAR(1),G4),_Data!B2:B111)),ROW(_Data!B2:B111)-1),2)),"")} | G10: {=IFERROR(INDEX(_Data!G2:G111,SMALL(IF(ISNUMBER(SEARCH(IF(G4="",CHAR(1),G4),_Data!B2:B111)),ROW(_Data!B2:B111)-1),2)),"")} | H10: {=IFERROR(INDEX(_Data!H2:H111,SMALL(IF(ISNUMBER(SEARCH(IF(G4="",CHAR(1),G4),_Data!B2:B111)),ROW(_Data!B2:B111)-1),2)),"")} | I10: {=IFERROR(INDEX(_Data!I2:I111,SMALL(IF(ISNUMBER(SEARCH(IF(G4="",CHAR(1),G4),_Data!B2:B111)),ROW(_Data!B2:B111)-1),2)),"")} | J10: {=IFERROR(INDEX(_Data!J2:J111,SMALL(IF(ISNUMBER(SEARCH(IF(G4="",CHAR(1),G4),_Data!B2:B111)),ROW(_Data!B2:B111)-1),2)),"")} | K10: {=IFERROR(INDEX(_Data!K2:K111,SMALL(IF(ISNUMBER(SEARCH(IF(G4="",CHAR(1),G4),_Data!B2:B111)),ROW(_Data!B2:B111)-1),2)),"")} | L10: {=IFERROR(INDEX(_Data!L2:L111,SMALL(IF(ISNUMBER(SEARCH(IF(G4="",CHAR(1),G4),_Data!B2:B111)),ROW(_Data!B2:B111)-1),2)),"")} | M10: {=IFERROR(INDEX(_Data!M2:M111,SMALL(IF(ISNUMBER(SEARCH(IF(G4="",CHAR(1),G4),_Data!B2:B111)),ROW(_Data!B2:B111)-1),2)),"")} | N10: {=IFERROR(INDEX(_Data!N2:N111,SMALL(IF(ISNUMBER(SEARCH(IF(G4="",CHAR(1),G4),_Data!B2:B111)),ROW(_Data!B2:B111)-1),2)),"")} | O10: {=IFERROR(INDEX(_Data!O2:O111,SMALL(IF(ISNUMBER(SEARCH(IF(G4="",CHAR(1),G4),_Data!B2:B111)),ROW(_Data!B2:B111)-1),2)),"")}
A11: {=IFERROR(INDEX(_Data!A2:A111,SMALL(IF(ISNUMBER(SEARCH(IF(G4="",CHAR(1),G4),_Data!B2:B111)),ROW(_Data!B2:B111)-1),3)),"")} | B11: {=IFERROR(INDEX(_Data!B2:B111,SMALL(IF(ISNUMBER(SEARCH(IF(G4="",CHAR(1),G4),_Data!B2:B111)),ROW(_Data!B2:B111)-1),3)),"")} | C11: {=IFERROR(INDEX(_Data!C2:C111,SMALL(IF(ISNUMBER(SEARCH(IF(G4="",CHAR(1),G4),_Data!B2:B111)),ROW(_Data!B2:B111)-1),3)),"")} | D11: {=IFERROR(INDEX(_Data!D2:D111,SMALL(IF(ISNUMBER(SEARCH(IF(G4="",CHAR(1),G4),_Data!B2:B111)),ROW(_Data!B2:B111)-1),3)),"")} | E11: {=IFERROR(INDEX(_Data!E2:E111,SMALL(IF(ISNUMBER(SEARCH(IF(G4="",CHAR(1),G4),_Data!B2:B111)),ROW(_Data!B2:B111)-1),3)),"")} | F11: {=IFERROR(INDEX(_Data!F2:F111,SMALL(IF(ISNUMBER(SEARCH(IF(G4="",CHAR(1),G4),_Data!B2:B111)),ROW(_Data!B2:B111)-1),3)),"")} | G11: {=IFERROR(INDEX(_Data!G2:G111,SMALL(IF(ISNUMBER(SEARCH(IF(G4="",CHAR(1),G4),_Data!B2:B111)),ROW(_Data!B2:B111)-1),3)),"")} | H11: {=IFERROR(INDEX(_Data!H2:H111,SMALL(IF(ISNUMBER(SEARCH(IF(G4="",CHAR(1),G4),_Data!B2:B111)),ROW(_Data!B2:B111)-1),3)),"")} | I11: {=IFERROR(INDEX(_Data!I2:I111,SMALL(IF(ISNUMBER(SEARCH(IF(G4="",CHAR(1),G4),_Data!B2:B111)),ROW(_Data!B2:B111)-1),3)),"")} | J11: {=IFERROR(INDEX(_Data!J2:J111,SMALL(IF(ISNUMBER(SEARCH(IF(G4="",CHAR(1),G4),_Data!B2:B111)),ROW(_Data!B2:B111)-1),3)),"")} | K11: {=IFERROR(INDEX(_Data!K2:K111,SMALL(IF(ISNUMBER(SEARCH(IF(G4="",CHAR(1),G4),_Data!B2:B111)),ROW(_Data!B2:B111)-1),3)),"")} | L11: {=IFERROR(INDEX(_Data!L2:L111,SMALL(IF(ISNUMBER(SEARCH(IF(G4="",CHAR(1),G4),_Data!B2:B111)),ROW(_Data!B2:B111)-1),3)),"")} | M11: {=IFERROR(INDEX(_Data!M2:M111,SMALL(IF(ISNUMBER(SEARCH(IF(G4="",CHAR(1),G4),_Data!B2:B111)),ROW(_Data!B2:B111)-1),3)),"")} | N11: {=IFERROR(INDEX(_Data!N2:N111,SMALL(IF(ISNUMBER(SEARCH(IF(G4="",CHAR(1),G4),_Data!B2:B111)),ROW(_Data!B2:B111)-1),3)),"")} | O11: {=IFERROR(INDEX(_Data!O2:O111,SMALL(IF(ISNUMBER(SEARCH(IF(G4="",CHAR(1),G4),_Data!B2:B111)),ROW(_Data!B2:B111)-1),3)),"")}
A12: {=IFERROR(INDEX(_Data!A2:A111,SMALL(IF(ISNUMBER(SEARCH(IF(G4="",CHAR(1),G4),_Data!B2:B111)),ROW(_Data!B2:B111)-1),4)),"")} | B12: {=IFERROR(INDEX(_Data!B2:B111,SMALL(IF(ISNUMBER(SEARCH(IF(G4="",CHAR(1),G4),_Data!B2:B111)),ROW(_Data!B2:B111)-1),4)),"")} | C12: {=IFERROR(INDEX(_Data!C2:C111,SMALL(IF(ISNUMBER(SEARCH(IF(G4="",CHAR(1),G4),_Data!B2:B111)),ROW(_Data!B2:B111)-1),4)),"")} | D12: {=IFERROR(INDEX(_Data!D2:D111,SMALL(IF(ISNUMBER(SEARCH(IF(G4="",CHAR(1),G4),_Data!B2:B111)),ROW(_Data!B2:B111)-1),4)),"")} | E12: {=IFERROR(INDEX(_Data!E2:E111,SMALL(IF(ISNUMBER(SEARCH(IF(G4="",CHAR(1),G4),_Data!B2:B111)),ROW(_Data!B2:B111)-1),4)),"")} | F12: {=IFERROR(INDEX(_Data!F2:F111,SMALL(IF(ISNUMBER(SEARCH(IF(G4="",CHAR(1),G4),_Data!B2:B111)),ROW(_Data!B2:B111)-1),4)),"")} | G12: {=IFERROR(INDEX(_Data!G2:G111,SMALL(IF(ISNUMBER(SEARCH(IF(G4="",CHAR(1),G4),_Data!B2:B111)),ROW(_Data!B2:B111)-1),4)),"")} | H12: {=IFERROR(INDEX(_Data!H2:H111,SMALL(IF(ISNUMBER(SEARCH(IF(G4="",CHAR(1),G4),_Data!B2:B111)),ROW(_Data!B2:B111)-1),4)),"")} | I12: {=IFERROR(INDEX(_Data!I2:I111,SMALL(IF(ISNUMBER(SEARCH(IF(G4="",CHAR(1),G4),_Data!B2:B111)),ROW(_Data!B2:B111)-1),4)),"")} | J12: {=IFERROR(INDEX(_Data!J2:J111,SMALL(IF(ISNUMBER(SEARCH(IF(G4="",CHAR(1),G4),_Data!B2:B111)),ROW(_Data!B2:B111)-1),4)),"")} | K12: {=IFERROR(INDEX(_Data!K2:K111,SMALL(IF(ISNUMBER(SEARCH(IF(G4="",CHAR(1),G4),_Data!B2:B111)),ROW(_Data!B2:B111)-1),4)),"")} | L12: {=IFERROR(INDEX(_Data!L2:L111,SMALL(IF(ISNUMBER(SEARCH(IF(G4="",CHAR(1),G4),_Data!B2:B111)),ROW(_Data!B2:B111)-1),4)),"")} | M12: {=IFERROR(INDEX(_Data!M2:M111,SMALL(IF(ISNUMBER(SEARCH(IF(G4="",CHAR(1),G4),_Data!B2:B111)),ROW(_Data!B2:B111)-1),4)),"")} | N12: {=IFERROR(INDEX(_Data!N2:N111,SMALL(IF(ISNUMBER(SEARCH(IF(G4="",CHAR(1),G4),_Data!B2:B111)),ROW(_Data!B2:B111)-1),4)),"")} | O12: {=IFERROR(INDEX(_Data!O2:O111,SMALL(IF(ISNUMBER(SEARCH(IF(G4="",CHAR(1),G4),_Data!B2:B111)),ROW(_Data!B2:B111)-1),4)),"")}
A13: {=IFERROR(INDEX(_Data!A2:A111,SMALL(IF(ISNUMBER(SEARCH(IF(G4="",CHAR(1),G4),_Data!B2:B111)),ROW(_Data!B2:B111)-1),5)),"")} | B13: {=IFERROR(INDEX(_Data!B2:B111,SMALL(IF(ISNUMBER(SEARCH(IF(G4="",CHAR(1),G4),_Data!B2:B111)),ROW(_Data!B2:B111)-1),5)),"")} | C13: {=IFERROR(INDEX(_Data!C2:C111,SMALL(IF(ISNUMBER(SEARCH(IF(G4="",CHAR(1),G4),_Data!B2:B111)),ROW(_Data!B2:B111)-1),5)),"")} | D13: {=IFERROR(INDEX(_Data!D2:D111,SMALL(IF(ISNUMBER(SEARCH(IF(G4="",CHAR(1),G4),_Data!B2:B111)),ROW(_Data!B2:B111)-1),5)),"")} | E13: {=IFERROR(INDEX(_Data!E2:E111,SMALL(IF(ISNUMBER(SEARCH(IF(G4="",CHAR(1),G4),_Data!B2:B111)),ROW(_Data!B2:B111)-1),5)),"")} | F13: {=IFERROR(INDEX(_Data!F2:F111,SMALL(IF(ISNUMBER(SEARCH(IF(G4="",CHAR(1),G4),_Data!B2:B111)),ROW(_Data!B2:B111)-1),5)),"")} | G13: {=IFERROR(INDEX(_Data!G2:G111,SMALL(IF(ISNUMBER(SEARCH(IF(G4="",CHAR(1),G4),_Data!B2:B111)),ROW(_Data!B2:B111)-1),5)),"")} | H13: {=IFERROR(INDEX(_Data!H2:H111,SMALL(IF(ISNUMBER(SEARCH(IF(G4="",CHAR(1),G4),_Data!B2:B111)),ROW(_Data!B2:B111)-1),5)),"")} | I13: {=IFERROR(INDEX(_Data!I2:I111,SMALL(IF(ISNUMBER(SEARCH(IF(G4="",CHAR(1),G4),_Data!B2:B111)),ROW(_Data!B2:B111)-1),5)),"")} | J13: {=IFERROR(INDEX(_Data!J2:J111,SMALL(IF(ISNUMBER(SEARCH(IF(G4="",CHAR(1),G4),_Data!B2:B111)),ROW(_Data!B2:B111)-1),5)),"")} | K13: {=IFERROR(INDEX(_Data!K2:K111,SMALL(IF(ISNUMBER(SEARCH(IF(G4="",CHAR(1),G4),_Data!B2:B111)),ROW(_Data!B2:B111)-1),5)),"")} | L13: {=IFERROR(INDEX(_Data!L2:L111,SMALL(IF(ISNUMBER(SEARCH(IF(G4="",CHAR(1),G4),_Data!B2:B111)),ROW(_Data!B2:B111)-1),5)),"")} | M13: {=IFERROR(INDEX(_Data!M2:M111,SMALL(IF(ISNUMBER(SEARCH(IF(G4="",CHAR(1),G4),_Data!B2:B111)),ROW(_Data!B2:B111)-1),5)),"")} | N13: {=IFERROR(INDEX(_Data!N2:N111,SMALL(IF(ISNUMBER(SEARCH(IF(G4="",CHAR(1),G4),_Data!B2:B111)),ROW(_Data!B2:B111)-1),5)),"")} | O13: {=IFERROR(INDEX(_Data!O2:O111,SMALL(IF(ISNUMBER(SEARCH(IF(G4="",CHAR(1),G4),_Data!B2:B111)),ROW(_Data!B2:B111)-1),5)),"")}
A14: {=IFERROR(INDEX(_Data!A2:A111,SMALL(IF(ISNUMBER(SEARCH(IF(G4="",CHAR(1),G4),_Data!B2:B111)),ROW(_Data!B2:B111)-1),6)),"")} | B14: {=IFERROR(INDEX(_Data!B2:B111,SMALL(IF(ISNUMBER(SEARCH(IF(G4="",CHAR(1),G4),_Data!B2:B111)),ROW(_Data!B2:B111)-1),6)),"")} | C14: {=IFERROR(INDEX(_Data!C2:C111,SMALL(IF(ISNUMBER(SEARCH(IF(G4="",CHAR(1),G4),_Data!B2:B111)),ROW(_Data!B2:B111)-1),6)),"")} | D14: {=IFERROR(INDEX(_Data!D2:D111,SMALL(IF(ISNUMBER(SEARCH(IF(G4="",CHAR(1),G4),_Data!B2:B111)),ROW(_Data!B2:B111)-1),6)),"")} | E14: {=IFERROR(INDEX(_Data!E2:E111,SMALL(IF(ISNUMBER(SEARCH(IF(G4="",CHAR(1),G4),_Data!B2:B111)),ROW(_Data!B2:B111)-1),6)),"")} | F14: {=IFERROR(INDEX(_Data!F2:F111,SMALL(IF(ISNUMBER(SEARCH(IF(G4="",CHAR(1),G4),_Data!B2:B111)),ROW(_Data!B2:B111)-1),6)),"")} | G14: {=IFERROR(INDEX(_Data!G2:G111,SMALL(IF(ISNUMBER(SEARCH(IF(G4="",CHAR(1),G4),_Data!B2:B111)),ROW(_Data!B2:B111)-1),6)),"")} | H14: {=IFERROR(INDEX(_Data!H2:H111,SMALL(IF(ISNUMBER(SEARCH(IF(G4="",CHAR(1),G4),_Data!B2:B111)),ROW(_Data!B2:B111)-1),6)),"")} | I14: {=IFERROR(INDEX(_Data!I2:I111,SMALL(IF(ISNUMBER(SEARCH(IF(G4="",CHAR(1),G4),_Data!B2:B111)),ROW(_Data!B2:B111)-1),6)),"")} | J14: {=IFERROR(INDEX(_Data!J2:J111,SMALL(IF(ISNUMBER(SEARCH(IF(G4="",CHAR(1),G4),_Data!B2:B111)),ROW(_Data!B2:B111)-1),6)),"")} | K14: {=IFERROR(INDEX(_Data!K2:K111,SMALL(IF(ISNUMBER(SEARCH(IF(G4="",CHAR(1),G4),_Data!B2:B111)),ROW(_Data!B2:B111)-1),6)),"")} | L14: {=IFERROR(INDEX(_Data!L2:L111,SMALL(IF(ISNUMBER(SEARCH(IF(G4="",CHAR(1),G4),_Data!B2:B111)),ROW(_Data!B2:B111)-1),6)),"")} | M14: {=IFERROR(INDEX(_Data!M2:M111,SMALL(IF(ISNUMBER(SEARCH(IF(G4="",CHAR(1),G4),_Data!B2:B111)),ROW(_Data!B2:B111)-1),6)),"")} | N14: {=IFERROR(INDEX(_Data!N2:N111,SMALL(IF(ISNUMBER(SEARCH(IF(G4="",CHAR(1),G4),_Data!B2:B111)),ROW(_Data!B2:B111)-1),6)),"")} | O14: {=IFERROR(INDEX(_Data!O2:O111,SMALL(IF(ISNUMBER(SEARCH(IF(G4="",CHAR(1),G4),_Data!B2:B111)),ROW(_Data!B2:B111)-1),6)),"")}
A15: {=IFERROR(INDEX(_Data!A2:A111,SMALL(IF(ISNUMBER(SEARCH(IF(G4="",CHAR(1),G4),_Data!B2:B111)),ROW(_Data!B2:B111)-1),7)),"")} | B15: {=IFERROR(INDEX(_Data!B2:B111,SMALL(IF(ISNUMBER(SEARCH(IF(G4="",CHAR(1),G4),_Data!B2:B111)),ROW(_Data!B2:B111)-1),7)),"")} | C15: {=IFERROR(INDEX(_Data!C2:C111,SMALL(IF(ISNUMBER(SEARCH(IF(G4="",CHAR(1),G4),_Data!B2:B111)),ROW(_Data!B2:B111)-1),7)),"")} | D15: {=IFERROR(INDEX(_Data!D2:D111,SMALL(IF(ISNUMBER(SEARCH(IF(G4="",CHAR(1),G4),_Data!B2:B111)),ROW(_Data!B2:B111)-1),7)),"")} | E15: {=IFERROR(INDEX(_Data!E2:E111,SMALL(IF(ISNUMBER(SEARCH(IF(G4="",CHAR(1),G4),_Data!B2:B111)),ROW(_Data!B2:B111)-1),7)),"")} | F15: {=IFERROR(INDEX(_Data!F2:F111,SMALL(IF(ISNUMBER(SEARCH(IF(G4="",CHAR(1),G4),_Data!B2:B111)),ROW(_Data!B2:B111)-1),7)),"")} | G15: {=IFERROR(INDEX(_Data!G2:G111,SMALL(IF(ISNUMBER(SEARCH(IF(G4="",CHAR(1),G4),_Data!B2:B111)),ROW(_Data!B2:B111)-1),7)),"")} | H15: {=IFERROR(INDEX(_Data!H2:H111,SMALL(IF(ISNUMBER(SEARCH(IF(G4="",CHAR(1),G4),_Data!B2:B111)),ROW(_Data!B2:B111)-1),7)),"")} | I15: {=IFERROR(INDEX(_Data!I2:I111,SMALL(IF(ISNUMBER(SEARCH(IF(G4="",CHAR(1),G4),_Data!B2:B111)),ROW(_Data!B2:B111)-1),7)),"")} | J15: {=IFERROR(INDEX(_Data!J2:J111,SMALL(IF(ISNUMBER(SEARCH(IF(G4="",CHAR(1),G4),_Data!B2:B111)),ROW(_Data!B2:B111)-1),7)),"")} | K15: {=IFERROR(INDEX(_Data!K2:K111,SMALL(IF(ISNUMBER(SEARCH(IF(G4="",CHAR(1),G4),_Data!B2:B111)),ROW(_Data!B2:B111)-1),7)),"")} | L15: {=IFERROR(INDEX(_Data!L2:L111,SMALL(IF(ISNUMBER(SEARCH(IF(G4="",CHAR(1),G4),_Data!B2:B111)),ROW(_Data!B2:B111)-1),7)),"")} | M15: {=IFERROR(INDEX(_Data!M2:M111,SMALL(IF(ISNUMBER(SEARCH(IF(G4="",CHAR(1),G4),_Data!B2:B111)),ROW(_Data!B2:B111)-1),7)),"")} | N15: {=IFERROR(INDEX(_Data!N2:N111,SMALL(IF(ISNUMBER(SEARCH(IF(G4="",CHAR(1),G4),_Data!B2:B111)),ROW(_Data!B2:B111)-1),7)),"")} | O15: {=IFERROR(INDEX(_Data!O2:O111,SMALL(IF(ISNUMBER(SEARCH(IF(G4="",CHAR(1),G4),_Data!B2:B111)),ROW(_Data!B2:B111)-1),7)),"")}
A16: {=IFERROR(INDEX(_Data!A2:A111,SMALL(IF(ISNUMBER(SEARCH(IF(G4="",CHAR(1),G4),_Data!B2:B111)),ROW(_Data!B2:B111)-1),8)),"")} | B16: {=IFERROR(INDEX(_Data!B2:B111,SMALL(IF(ISNUMBER(SEARCH(IF(G4="",CHAR(1),G4),_Data!B2:B111)),ROW(_Data!B2:B111)-1),8)),"")} | C16: {=IFERROR(INDEX(_Data!C2:C111,SMALL(IF(ISNUMBER(SEARCH(IF(G4="",CHAR(1),G4),_Data!B2:B111)),ROW(_Data!B2:B111)-1),8)),"")} | D16: {=IFERROR(INDEX(_Data!D2:D111,SMALL(IF(ISNUMBER(SEARCH(IF(G4="",CHAR(1),G4),_Data!B2:B111)),ROW(_Data!B2:B111)-1),8)),"")} | E16: {=IFERROR(INDEX(_Data!E2:E111,SMALL(IF(ISNUMBER(SEARCH(IF(G4="",CHAR(1),G4),_Data!B2:B111)),ROW(_Data!B2:B111)-1),8)),"")} | F16: {=IFERROR(INDEX(_Data!F2:F111,SMALL(IF(ISNUMBER(SEARCH(IF(G4="",CHAR(1),G4),_Data!B2:B111)),ROW(_Data!B2:B111)-1),8)),"")} | G16: {=IFERROR(INDEX(_Data!G2:G111,SMALL(IF(ISNUMBER(SEARCH(IF(G4="",CHAR(1),G4),_Data!B2:B111)),ROW(_Data!B2:B111)-1),8)),"")} | H16: {=IFERROR(INDEX(_Data!H2:H111,SMALL(IF(ISNUMBER(SEARCH(IF(G4="",CHAR(1),G4),_Data!B2:B111)),ROW(_Data!B2:B111)-1),8)),"")} | I16: {=IFERROR(INDEX(_Data!I2:I111,SMALL(IF(ISNUMBER(SEARCH(IF(G4="",CHAR(1),G4),_Data!B2:B111)),ROW(_Data!B2:B111)-1),8)),"")} | J16: {=IFERROR(INDEX(_Data!J2:J111,SMALL(IF(ISNUMBER(SEARCH(IF(G4="",CHAR(1),G4),_Data!B2:B111)),ROW(_Data!B2:B111)-1),8)),"")} | K16: {=IFERROR(INDEX(_Data!K2:K111,SMALL(IF(ISNUMBER(SEARCH(IF(G4="",CHAR(1),G4),_Data!B2:B111)),ROW(_Data!B2:B111)-1),8)),"")} | L16: {=IFERROR(INDEX(_Data!L2:L111,SMALL(IF(ISNUMBER(SEARCH(IF(G4="",CHAR(1),G4),_Data!B2:B111)),ROW(_Data!B2:B111)-1),8)),"")} | M16: {=IFERROR(INDEX(_Data!M2:M111,SMALL(IF(ISNUMBER(SEARCH(IF(G4="",CHAR(1),G4),_Data!B2:B111)),ROW(_Data!B2:B111)-1),8)),"")} | N16: {=IFERROR(INDEX(_Data!N2:N111,SMALL(IF(ISNUMBER(SEARCH(IF(G4="",CHAR(1),G4),_Data!B2:B111)),ROW(_Data!B2:B111)-1),8)),"")} | O16: {=IFERROR(INDEX(_Data!O2:O111,SMALL(IF(ISNUMBER(SEARCH(IF(G4="",CHAR(1),G4),_Data!B2:B111)),ROW(_Data!B2:B111)-1),8)),"")}
A17: {=IFERROR(INDEX(_Data!A2:A111,SMALL(IF(ISNUMBER(SEARCH(IF(G4="",CHAR(1),G4),_Data!B2:B111)),ROW(_Data!B2:B111)-1),9)),"")} | B17: {=IFERROR(INDEX(_Data!B2:B111,SMALL(IF(ISNUMBER(SEARCH(IF(G4="",CHAR(1),G4),_Data!B2:B111)),ROW(_Data!B2:B111)-1),9)),"")} | C17: {=IFERROR(INDEX(_Data!C2:C111,SMALL(IF(ISNUMBER(SEARCH(IF(G4="",CHAR(1),G4),_Data!B2:B111)),ROW(_Data!B2:B111)-1),9)),"")} | D17: {=IFERROR(INDEX(_Data!D2:D111,SMALL(IF(ISNUMBER(SEARCH(IF(G4="",CHAR(1),G4),_Data!B2:B111)),ROW(_Data!B2:B111)-1),9)),"")} | E17: {=IFERROR(INDEX(_Data!E2:E111,SMALL(IF(ISNUMBER(SEARCH(IF(G4="",CHAR(1),G4),_Data!B2:B111)),ROW(_Data!B2:B111)-1),9)),"")} | F17: {=IFERROR(INDEX(_Data!F2:F111,SMALL(IF(ISNUMBER(SEARCH(IF(G4="",CHAR(1),G4),_Data!B2:B111)),ROW(_Data!B2:B111)-1),9)),"")} | G17: {=IFERROR(INDEX(_Data!G2:G111,SMALL(IF(ISNUMBER(SEARCH(IF(G4="",CHAR(1),G4),_Data!B2:B111)),ROW(_Data!B2:B111)-1),9)),"")} | H17: {=IFERROR(INDEX(_Data!H2:H111,SMALL(IF(ISNUMBER(SEARCH(IF(G4="",CHAR(1),G4),_Data!B2:B111)),ROW(_Data!B2:B111)-1),9)),"")} | I17: {=IFERROR(INDEX(_Data!I2:I111,SMALL(IF(ISNUMBER(SEARCH(IF(G4="",CHAR(1),G4),_Data!B2:B111)),ROW(_Data!B2:B111)-1),9)),"")} | J17: {=IFERROR(INDEX(_Data!J2:J111,SMALL(IF(ISNUMBER(SEARCH(IF(G4="",CHAR(1),G4),_Data!B2:B111)),ROW(_Data!B2:B111)-1),9)),"")} | K17: {=IFERROR(INDEX(_Data!K2:K111,SMALL(IF(ISNUMBER(SEARCH(IF(G4="",CHAR(1),G4),_Data!B2:B111)),ROW(_Data!B2:B111)-1),9)),"")} | L17: {=IFERROR(INDEX(_Data!L2:L111,SMALL(IF(ISNUMBER(SEARCH(IF(G4="",CHAR(1),G4),_Data!B2:B111)),ROW(_Data!B2:B111)-1),9)),"")} | M17: {=IFERROR(INDEX(_Data!M2:M111,SMALL(IF(ISNUMBER(SEARCH(IF(G4="",CHAR(1),G4),_Data!B2:B111)),ROW(_Data!B2:B111)-1),9)),"")} | N17: {=IFERROR(INDEX(_Data!N2:N111,SMALL(IF(ISNUMBER(SEARCH(IF(G4="",CHAR(1),G4),_Data!B2:B111)),ROW(_Data!B2:B111)-1),9)),"")} | O17: {=IFERROR(INDEX(_Data!O2:O111,SMALL(IF(ISNUMBER(SEARCH(IF(G4="",CHAR(1),G4),_Data!B2:B111)),ROW(_Data!B2:B111)-1),9)),"")}
A18: {=IFERROR(INDEX(_Data!A2:A111,SMALL(IF(ISNUMBER(SEARCH(IF(G4="",CHAR(1),G4),_Data!B2:B111)),ROW(_Data!B2:B111)-1),10)),"")} | B18: {=IFERROR(INDEX(_Data!B2:B111,SMALL(IF(ISNUMBER(SEARCH(IF(G4="",CHAR(1),G4),_Data!B2:B111)),ROW(_Data!B2:B111)-1),10)),"")} | C18: {=IFERROR(INDEX(_Data!C2:C111,SMALL(IF(ISNUMBER(SEARCH(IF(G4="",CHAR(1),G4),_Data!B2:B111)),ROW(_Data!B2:B111)-1),10)),"")} | D18: {=IFERROR(INDEX(_Data!D2:D111,SMALL(IF(ISNUMBER(SEARCH(IF(G4="",CHAR(1),G4),_Data!B2:B111)),ROW(_Data!B2:B111)-1),10)),"")} | E18: {=IFERROR(INDEX(_Data!E2:E111,SMALL(IF(ISNUMBER(SEARCH(IF(G4="",CHAR(1),G4),_Data!B2:B111)),ROW(_Data!B2:B111)-1),10)),"")} | F18: {=IFERROR(INDEX(_Data!F2:F111,SMALL(IF(ISNUMBER(SEARCH(IF(G4="",CHAR(1),G4),_Data!B2:B111)),ROW(_Data!B2:B111)-1),10)),"")} | G18: {=IFERROR(INDEX(_Data!G2:G111,SMALL(IF(ISNUMBER(SEARCH(IF(G4="",CHAR(1),G4),_Data!B2:B111)),ROW(_Data!B2:B111)-1),10)),"")} | H18: {=IFERROR(INDEX(_Data!H2:H111,SMALL(IF(ISNUMBER(SEARCH(IF(G4="",CHAR(1),G4),_Data!B2:B111)),ROW(_Data!B2:B111)-1),10)),"")} | I18: {=IFERROR(INDEX(_Data!I2:I111,SMALL(IF(ISNUMBER(SEARCH(IF(G4="",CHAR(1),G4),_Data!B2:B111)),ROW(_Data!B2:B111)-1),10)),"")} | J18: {=IFERROR(INDEX(_Data!J2:J111,SMALL(IF(ISNUMBER(SEARCH(IF(G4="",CHAR(1),G4),_Data!B2:B111)),ROW(_Data!B2:B111)-1),10)),"")} | K18: {=IFERROR(INDEX(_Data!K2:K111,SMALL(IF(ISNUMBER(SEARCH(IF(G4="",CHAR(1),G4),_Data!B2:B111)),ROW(_Data!B2:B111)-1),10)),"")} | L18: {=IFERROR(INDEX(_Data!L2:L111,SMALL(IF(ISNUMBER(SEARCH(IF(G4="",CHAR(1),G4),_Data!B2:B111)),ROW(_Data!B2:B111)-1),10)),"")} | M18: {=IFERROR(INDEX(_Data!M2:M111,SMALL(IF(ISNUMBER(SEARCH(IF(G4="",CHAR(1),G4),_Data!B2:B111)),ROW(_Data!B2:B111)-1),10)),"")} | N18: {=IFERROR(INDEX(_Data!N2:N111,SMALL(IF(ISNUMBER(SEARCH(IF(G4="",CHAR(1),G4),_Data!B2:B111)),ROW(_Data!B2:B111)-1),10)),"")} | O18: {=IFERROR(INDEX(_Data!O2:O111,SMALL(IF(ISNUMBER(SEARCH(IF(G4="",CHAR(1),G4),_Data!B2:B111)),ROW(_Data!B2:B111)-1),10)),"")}
A19: {=IFERROR(INDEX(_Data!A2:A111,SMALL(IF(ISNUMBER(SEARCH(IF(G4="",CHAR(1),G4),_Data!B2:B111)),ROW(_Data!B2:B111)-1),11)),"")} | B19: {=IFERROR(INDEX(_Data!B2:B111,SMALL(IF(ISNUMBER(SEARCH(IF(G4="",CHAR(1),G4),_Data!B2:B111)),ROW(_Data!B2:B111)-1),11)),"")} | C19: {=IFERROR(INDEX(_Data!C2:C111,SMALL(IF(ISNUMBER(SEARCH(IF(G4="",CHAR(1),G4),_Data!B2:B111)),ROW(_Data!B2:B111)-1),11)),"")} | D19: {=IFERROR(INDEX(_Data!D2:D111,SMALL(IF(ISNUMBER(SEARCH(IF(G4="",CHAR(1),G4),_Data!B2:B111)),ROW(_Data!B2:B111)-1),11)),"")} | E19: {=IFERROR(INDEX(_Data!E2:E111,SMALL(IF(ISNUMBER(SEARCH(IF(G4="",CHAR(1),G4),_Data!B2:B111)),ROW(_Data!B2:B111)-1),11)),"")} | F19: {=IFERROR(INDEX(_Data!F2:F111,SMALL(IF(ISNUMBER(SEARCH(IF(G4="",CHAR(1),G4),_Data!B2:B111)),ROW(_Data!B2:B111)-1),11)),"")} | G19: {=IFERROR(INDEX(_Data!G2:G111,SMALL(IF(ISNUMBER(SEARCH(IF(G4="",CHAR(1),G4),_Data!B2:B111)),ROW(_Data!B2:B111)-1),11)),"")} | H19: {=IFERROR(INDEX(_Data!H2:H111,SMALL(IF(ISNUMBER(SEARCH(IF(G4="",CHAR(1),G4),_Data!B2:B111)),ROW(_Data!B2:B111)-1),11)),"")} | I19: {=IFERROR(INDEX(_Data!I2:I111,SMALL(IF(ISNUMBER(SEARCH(IF(G4="",CHAR(1),G4),_Data!B2:B111)),ROW(_Data!B2:B111)-1),11)),"")} | J19: {=IFERROR(INDEX(_Data!J2:J111,SMALL(IF(ISNUMBER(SEARCH(IF(G4="",CHAR(1),G4),_Data!B2:B111)),ROW(_Data!B2:B111)-1),11)),"")} | K19: {=IFERROR(INDEX(_Data!K2:K111,SMALL(IF(ISNUMBER(SEARCH(IF(G4="",CHAR(1),G4),_Data!B2:B111)),ROW(_Data!B2:B111)-1),11)),"")} | L19: {=IFERROR(INDEX(_Data!L2:L111,SMALL(IF(ISNUMBER(SEARCH(IF(G4="",CHAR(1),G4),_Data!B2:B111)),ROW(_Data!B2:B111)-1),11)),"")} | M19: {=IFERROR(INDEX(_Data!M2:M111,SMALL(IF(ISNUMBER(SEARCH(IF(G4="",CHAR(1),G4),_Data!B2:B111)),ROW(_Data!B2:B111)-1),11)),"")} | N19: {=IFERROR(INDEX(_Data!N2:N111,SMALL(IF(ISNUMBER(SEARCH(IF(G4="",CHAR(1),G4),_Data!B2:B111)),ROW(_Data!B2:B111)-1),11)),"")} | O19: {=IFERROR(INDEX(_Data!O2:O111,SMALL(IF(ISNUMBER(SEARCH(IF(G4="",CHAR(1),G4),_Data!B2:B111)),ROW(_Data!B2:B111)-1),11)),"")}
A20: {=IFERROR(INDEX(_Data!A2:A111,SMALL(IF(ISNUMBER(SEARCH(IF(G4="",CHAR(1),G4),_Data!B2:B111)),ROW(_Data!B2:B111)-1),12)),"")} | B20: {=IFERROR(INDEX(_Data!B2:B111,SMALL(IF(ISNUMBER(SEARCH(IF(G4="",CHAR(1),G4),_Data!B2:B111)),ROW(_Data!B2:B111)-1),12)),"")} | C20: {=IFERROR(INDEX(_Data!C2:C111,SMALL(IF(ISNUMBER(SEARCH(IF(G4="",CHAR(1),G4),_Data!B2:B111)),ROW(_Data!B2:B111)-1),12)),"")} | D20: {=IFERROR(INDEX(_Data!D2:D111,SMALL(IF(ISNUMBER(SEARCH(IF(G4="",CHAR(1),G4),_Data!B2:B111)),ROW(_Data!B2:B111)-1),12)),"")} | E20: {=IFERROR(INDEX(_Data!E2:E111,SMALL(IF(ISNUMBER(SEARCH(IF(G4="",CHAR(1),G4),_Data!B2:B111)),ROW(_Data!B2:B111)-1),12)),"")} | F20: {=IFERROR(INDEX(_Data!F2:F111,SMALL(IF(ISNUMBER(SEARCH(IF(G4="",CHAR(1),G4),_Data!B2:B111)),ROW(_Data!B2:B111)-1),12)),"")} | G20: {=IFERROR(INDEX(_Data!G2:G111,SMALL(IF(ISNUMBER(SEARCH(IF(G4="",CHAR(1),G4),_Data!B2:B111)),ROW(_Data!B2:B111)-1),12)),"")} | H20: {=IFERROR(INDEX(_Data!H2:H111,SMALL(IF(ISNUMBER(SEARCH(IF(G4="",CHAR(1),G4),_Data!B2:B111)),ROW(_Data!B2:B111)-1),12)),"")} | I20: {=IFERROR(INDEX(_Data!I2:I111,SMALL(IF(ISNUMBER(SEARCH(IF(G4="",CHAR(1),G4),_Data!B2:B111)),ROW(_Data!B2:B111)-1),12)),"")} | J20: {=IFERROR(INDEX(_Data!J2:J111,SMALL(IF(ISNUMBER(SEARCH(IF(G4="",CHAR(1),G4),_Data!B2:B111)),ROW(_Data!B2:B111)-1),12)),"")} | K20: {=IFERROR(INDEX(_Data!K2:K111,SMALL(IF(ISNUMBER(SEARCH(IF(G4="",CHAR(1),G4),_Data!B2:B111)),ROW(_Data!B2:B111)-1),12)),"")} | L20: {=IFERROR(INDEX(_Data!L2:L111,SMALL(IF(ISNUMBER(SEARCH(IF(G4="",CHAR(1),G4),_Data!B2:B111)),ROW(_Data!B2:B111)-1),12)),"")} | M20: {=IFERROR(INDEX(_Data!M2:M111,SMALL(IF(ISNUMBER(SEARCH(IF(G4="",CHAR(1),G4),_Data!B2:B111)),ROW(_Data!B2:B111)-1),12)),"")} | N20: {=IFERROR(INDEX(_Data!N2:N111,SMALL(IF(ISNUMBER(SEARCH(IF(G4="",CHAR(1),G4),_Data!B2:B111)),ROW(_Data!B2:B111)-1),12)),"")} | O20: {=IFERROR(INDEX(_Data!O2:O111,SMALL(IF(ISNUMBER(SEARCH(IF(G4="",CHAR(1),G4),_Data!B2:B111)),ROW(_Data!B2:B111)-1),12)),"")}
A21: {=IFERROR(INDEX(_Data!A2:A111,SMALL(IF(ISNUMBER(SEARCH(IF(G4="",CHAR(1),G4),_Data!B2:B111)),ROW(_Data!B2:B111)-1),13)),"")} | B21: {=IFERROR(INDEX(_Data!B2:B111,SMALL(IF(ISNUMBER(SEARCH(IF(G4="",CHAR(1),G4),_Data!B2:B111)),ROW(_Data!B2:B111)-1),13)),"")} | C21: {=IFERROR(INDEX(_Data!C2:C111,SMALL(IF(ISNUMBER(SEARCH(IF(G4="",CHAR(1),G4),_Data!B2:B111)),ROW(_Data!B2:B111)-1),13)),"")} | D21: {=IFERROR(INDEX(_Data!D2:D111,SMALL(IF(ISNUMBER(SEARCH(IF(G4="",CHAR(1),G4),_Data!B2:B111)),ROW(_Data!B2:B111)-1),13)),"")} | E21: {=IFERROR(INDEX(_Data!E2:E111,SMALL(IF(ISNUMBER(SEARCH(IF(G4="",CHAR(1),G4),_Data!B2:B111)),ROW(_Data!B2:B111)-1),13)),"")} | F21: {=IFERROR(INDEX(_Data!F2:F111,SMALL(IF(ISNUMBER(SEARCH(IF(G4="",CHAR(1),G4),_Data!B2:B111)),ROW(_Data!B2:B111)-1),13)),"")} | G21: {=IFERROR(INDEX(_Data!G2:G111,SMALL(IF(ISNUMBER(SEARCH(IF(G4="",CHAR(1),G4),_Data!B2:B111)),ROW(_Data!B2:B111)-1),13)),"")} | H21: {=IFERROR(INDEX(_Data!H2:H111,SMALL(IF(ISNUMBER(SEARCH(IF(G4="",CHAR(1),G4),_Data!B2:B111)),ROW(_Data!B2:B111)-1),13)),"")} | I21: {=IFERROR(INDEX(_Data!I2:I111,SMALL(IF(ISNUMBER(SEARCH(IF(G4="",CHAR(1),G4),_Data!B2:B111)),ROW(_Data!B2:B111)-1),13)),"")} | J21: {=IFERROR(INDEX(_Data!J2:J111,SMALL(IF(ISNUMBER(SEARCH(IF(G4="",CHAR(1),G4),_Data!B2:B111)),ROW(_Data!B2:B111)-1),13)),"")} | K21: {=IFERROR(INDEX(_Data!K2:K111,SMALL(IF(ISNUMBER(SEARCH(IF(G4="",CHAR(1),G4),_Data!B2:B111)),ROW(_Data!B2:B111)-1),13)),"")} | L21: {=IFERROR(INDEX(_Data!L2:L111,SMALL(IF(ISNUMBER(SEARCH(IF(G4="",CHAR(1),G4),_Data!B2:B111)),ROW(_Data!B2:B111)-1),13)),"")} | M21: {=IFERROR(INDEX(_Data!M2:M111,SMALL(IF(ISNUMBER(SEARCH(IF(G4="",CHAR(1),G4),_Data!B2:B111)),ROW(_Data!B2:B111)-1),13)),"")} | N21: {=IFERROR(INDEX(_Data!N2:N111,SMALL(IF(ISNUMBER(SEARCH(IF(G4="",CHAR(1),G4),_Data!B2:B111)),ROW(_Data!B2:B111)-1),13)),"")} | O21: {=IFERROR(INDEX(_Data!O2:O111,SMALL(IF(ISNUMBER(SEARCH(IF(G4="",CHAR(1),G4),_Data!B2:B111)),ROW(_Data!B2:B111)-1),13)),"")}
A22: {=IFERROR(INDEX(_Data!A2:A111,SMALL(IF(ISNUMBER(SEARCH(IF(G4="",CHAR(1),G4),_Data!B2:B111)),ROW(_Data!B2:B111)-1),14)),"")} | B22: {=IFERROR(INDEX(_Data!B2:B111,SMALL(IF(ISNUMBER(SEARCH(IF(G4="",CHAR(1),G4),_Data!B2:B111)),ROW(_Data!B2:B111)-1),14)),"")} | C22: {=IFERROR(INDEX(_Data!C2:C111,SMALL(IF(ISNUMBER(SEARCH(IF(G4="",CHAR(1),G4),_Data!B2:B111)),ROW(_Data!B2:B111)-1),14)),"")} | D22: {=IFERROR(INDEX(_Data!D2:D111,SMALL(IF(ISNUMBER(SEARCH(IF(G4="",CHAR(1),G4),_Data!B2:B111)),ROW(_Data!B2:B111)-1),14)),"")} | E22: {=IFERROR(INDEX(_Data!E2:E111,SMALL(IF(ISNUMBER(SEARCH(IF(G4="",CHAR(1),G4),_Data!B2:B111)),ROW(_Data!B2:B111)-1),14)),"")} | F22: {=IFERROR(INDEX(_Data!F2:F111,SMALL(IF(ISNUMBER(SEARCH(IF(G4="",CHAR(1),G4),_Data!B2:B111)),ROW(_Data!B2:B111)-1),14)),"")} | G22: {=IFERROR(INDEX(_Data!G2:G111,SMALL(IF(ISNUMBER(SEARCH(IF(G4="",CHAR(1),G4),_Data!B2:B111)),ROW(_Data!B2:B111)-1),14)),"")} | H22: {=IFERROR(INDEX(_Data!H2:H111,SMALL(IF(ISNUMBER(SEARCH(IF(G4="",CHAR(1),G4),_Data!B2:B111)),ROW(_Data!B2:B111)-1),14)),"")} | I22: {=IFERROR(INDEX(_Data!I2:I111,SMALL(IF(ISNUMBER(SEARCH(IF(G4="",CHAR(1),G4),_Data!B2:B111)),ROW(_Data!B2:B111)-1),14)),"")} | J22: {=IFERROR(INDEX(_Data!J2:J111,SMALL(IF(ISNUMBER(SEARCH(IF(G4="",CHAR(1),G4),_Data!B2:B111)),ROW(_Data!B2:B111)-1),14)),"")} | K22: {=IFERROR(INDEX(_Data!K2:K111,SMALL(IF(ISNUMBER(SEARCH(IF(G4="",CHAR(1),G4),_Data!B2:B111)),ROW(_Data!B2:B111)-1),14)),"")} | L22: {=IFERROR(INDEX(_Data!L2:L111,SMALL(IF(ISNUMBER(SEARCH(IF(G4="",CHAR(1),G4),_Data!B2:B111)),ROW(_Data!B2:B111)-1),14)),"")} | M22: {=IFERROR(INDEX(_Data!M2:M111,SMALL(IF(ISNUMBER(SEARCH(IF(G4="",CHAR(1),G4),_Data!B2:B111)),ROW(_Data!B2:B111)-1),14)),"")} | N22: {=IFERROR(INDEX(_Data!N2:N111,SMALL(IF(ISNUMBER(SEARCH(IF(G4="",CHAR(1),G4),_Data!B2:B111)),ROW(_Data!B2:B111)-1),14)),"")} | O22: {=IFERROR(INDEX(_Data!O2:O111,SMALL(IF(ISNUMBER(SEARCH(IF(G4="",CHAR(1),G4),_Data!B2:B111)),ROW(_Data!B2:B111)-1),14)),"")}
A23: {=IFERROR(INDEX(_Data!A2:A111,SMALL(IF(ISNUMBER(SEARCH(IF(G4="",CHAR(1),G4),_Data!B2:B111)),ROW(_Data!B2:B111)-1),15)),"")} | B23: {=IFERROR(INDEX(_Data!B2:B111,SMALL(IF(ISNUMBER(SEARCH(IF(G4="",CHAR(1),G4),_Data!B2:B111)),ROW(_Data!B2:B111)-1),15)),"")} | C23: {=IFERROR(INDEX(_Data!C2:C111,SMALL(IF(ISNUMBER(SEARCH(IF(G4="",CHAR(1),G4),_Data!B2:B111)),ROW(_Data!B2:B111)-1),15)),"")} | D23: {=IFERROR(INDEX(_Data!D2:D111,SMALL(IF(ISNUMBER(SEARCH(IF(G4="",CHAR(1),G4),_Data!B2:B111)),ROW(_Data!B2:B111)-1),15)),"")} | E23: {=IFERROR(INDEX(_Data!E2:E111,SMALL(IF(ISNUMBER(SEARCH(IF(G4="",CHAR(1),G4),_Data!B2:B111)),ROW(_Data!B2:B111)-1),15)),"")} | F23: {=IFERROR(INDEX(_Data!F2:F111,SMALL(IF(ISNUMBER(SEARCH(IF(G4="",CHAR(1),G4),_Data!B2:B111)),ROW(_Data!B2:B111)-1),15)),"")} | G23: {=IFERROR(INDEX(_Data!G2:G111,SMALL(IF(ISNUMBER(SEARCH(IF(G4="",CHAR(1),G4),_Data!B2:B111)),ROW(_Data!B2:B111)-1),15)),"")} | H23: {=IFERROR(INDEX(_Data!H2:H111,SMALL(IF(ISNUMBER(SEARCH(IF(G4="",CHAR(1),G4),_Data!B2:B111)),ROW(_Data!B2:B111)-1),15)),"")} | I23: {=IFERROR(INDEX(_Data!I2:I111,SMALL(IF(ISNUMBER(SEARCH(IF(G4="",CHAR(1),G4),_Data!B2:B111)),ROW(_Data!B2:B111)-1),15)),"")} | J23: {=IFERROR(INDEX(_Data!J2:J111,SMALL(IF(ISNUMBER(SEARCH(IF(G4="",CHAR(1),G4),_Data!B2:B111)),ROW(_Data!B2:B111)-1),15)),"")} | K23: {=IFERROR(INDEX(_Data!K2:K111,SMALL(IF(ISNUMBER(SEARCH(IF(G4="",CHAR(1),G4),_Data!B2:B111)),ROW(_Data!B2:B111)-1),15)),"")} | L23: {=IFERROR(INDEX(_Data!L2:L111,SMALL(IF(ISNUMBER(SEARCH(IF(G4="",CHAR(1),G4),_Data!B2:B111)),ROW(_Data!B2:B111)-1),15)),"")} | M23: {=IFERROR(INDEX(_Data!M2:M111,SMALL(IF(ISNUMBER(SEARCH(IF(G4="",CHAR(1),G4),_Data!B2:B111)),ROW(_Data!B2:B111)-1),15)),"")} | N23: {=IFERROR(INDEX(_Data!N2:N111,SMALL(IF(ISNUMBER(SEARCH(IF(G4="",CHAR(1),G4),_Data!B2:B111)),ROW(_Data!B2:B111)-1),15)),"")} | O23: {=IFERROR(INDEX(_Data!O2:O111,SMALL(IF(ISNUMBER(SEARCH(IF(G4="",CHAR(1),G4),_Data!B2:B111)),ROW(_Data!B2:B111)-1),15)),"")}
A24: {=IFERROR(INDEX(_Data!A2:A111,SMALL(IF(ISNUMBER(SEARCH(IF(G4="",CHAR(1),G4),_Data!B2:B111)),ROW(_Data!B2:B111)-1),16)),"")} | B24: {=IFERROR(INDEX(_Data!B2:B111,SMALL(IF(ISNUMBER(SEARCH(IF(G4="",CHAR(1),G4),_Data!B2:B111)),ROW(_Data!B2:B111)-1),16)),"")} | C24: {=IFERROR(INDEX(_Data!C2:C111,SMALL(IF(ISNUMBER(SEARCH(IF(G4="",CHAR(1),G4),_Data!B2:B111)),ROW(_Data!B2:B111)-1),16)),"")} | D24: {=IFERROR(INDEX(_Data!D2:D111,SMALL(IF(ISNUMBER(SEARCH(IF(G4="",CHAR(1),G4),_Data!B2:B111)),ROW(_Data!B2:B111)-1),16)),"")} | E24: {=IFERROR(INDEX(_Data!E2:E111,SMALL(IF(ISNUMBER(SEARCH(IF(G4="",CHAR(1),G4),_Data!B2:B111)),ROW(_Data!B2:B111)-1),16)),"")} | F24: {=IFERROR(INDEX(_Data!F2:F111,SMALL(IF(ISNUMBER(SEARCH(IF(G4="",CHAR(1),G4),_Data!B2:B111)),ROW(_Data!B2:B111)-1),16)),"")} | G24: {=IFERROR(INDEX(_Data!G2:G111,SMALL(IF(ISNUMBER(SEARCH(IF(G4="",CHAR(1),G4),_Data!B2:B111)),ROW(_Data!B2:B111)-1),16)),"")} | H24: {=IFERROR(INDEX(_Data!H2:H111,SMALL(IF(ISNUMBER(SEARCH(IF(G4="",CHAR(1),G4),_Data!B2:B111)),ROW(_Data!B2:B111)-1),16)),"")} | I24: {=IFERROR(INDEX(_Data!I2:I111,SMALL(IF(ISNUMBER(SEARCH(IF(G4="",CHAR(1),G4),_Data!B2:B111)),ROW(_Data!B2:B111)-1),16)),"")} | J24: {=IFERROR(INDEX(_Data!J2:J111,SMALL(IF(ISNUMBER(SEARCH(IF(G4="",CHAR(1),G4),_Data!B2:B111)),ROW(_Data!B2:B111)-1),16)),"")} | K24: {=IFERROR(INDEX(_Data!K2:K111,SMALL(IF(ISNUMBER(SEARCH(IF(G4="",CHAR(1),G4),_Data!B2:B111)),ROW(_Data!B2:B111)-1),16)),"")} | L24: {=IFERROR(INDEX(_Data!L2:L111,SMALL(IF(ISNUMBER(SEARCH(IF(G4="",CHAR(1),G4),_Data!B2:B111)),ROW(_Data!B2:B111)-1),16)),"")} | M24: {=IFERROR(INDEX(_Data!M2:M111,SMALL(IF(ISNUMBER(SEARCH(IF(G4="",CHAR(1),G4),_Data!B2:B111)),ROW(_Data!B2:B111)-1),16)),"")} | N24: {=IFERROR(INDEX(_Data!N2:N111,SMALL(IF(ISNUMBER(SEARCH(IF(G4="",CHAR(1),G4),_Data!B2:B111)),ROW(_Data!B2:B111)-1),16)),"")} | O24: {=IFERROR(INDEX(_Data!O2:O111,SMALL(IF(ISNUMBER(SEARCH(IF(G4="",CHAR(1),G4),_Data!B2:B111)),ROW(_Data!B2:B111)-1),16)),"")}
A25: {=IFERROR(INDEX(_Data!A2:A111,SMALL(IF(ISNUMBER(SEARCH(IF(G4="",CHAR(1),G4),_Data!B2:B111)),ROW(_Data!B2:B111)-1),17)),"")} | B25: {=IFERROR(INDEX(_Data!B2:B111,SMALL(IF(ISNUMBER(SEARCH(IF(G4="",CHAR(1),G4),_Data!B2:B111)),ROW(_Data!B2:B111)-1),17)),"")} | C25: {=IFERROR(INDEX(_Data!C2:C111,SMALL(IF(ISNUMBER(SEARCH(IF(G4="",CHAR(1),G4),_Data!B2:B111)),ROW(_Data!B2:B111)-1),17)),"")} | D25: {=IFERROR(INDEX(_Data!D2:D111,SMALL(IF(ISNUMBER(SEARCH(IF(G4="",CHAR(1),G4),_Data!B2:B111)),ROW(_Data!B2:B111)-1),17)),"")} | E25: {=IFERROR(INDEX(_Data!E2:E111,SMALL(IF(ISNUMBER(SEARCH(IF(G4="",CHAR(1),G4),_Data!B2:B111)),ROW(_Data!B2:B111)-1),17)),"")} | F25: {=IFERROR(INDEX(_Data!F2:F111,SMALL(IF(ISNUMBER(SEARCH(IF(G4="",CHAR(1),G4),_Data!B2:B111)),ROW(_Data!B2:B111)-1),17)),"")} | G25: {=IFERROR(INDEX(_Data!G2:G111,SMALL(IF(ISNUMBER(SEARCH(IF(G4="",CHAR(1),G4),_Data!B2:B111)),ROW(_Data!B2:B111)-1),17)),"")} | H25: {=IFERROR(INDEX(_Data!H2:H111,SMALL(IF(ISNUMBER(SEARCH(IF(G4="",CHAR(1),G4),_Data!B2:B111)),ROW(_Data!B2:B111)-1),17)),"")} | I25: {=IFERROR(INDEX(_Data!I2:I111,SMALL(IF(ISNUMBER(SEARCH(IF(G4="",CHAR(1),G4),_Data!B2:B111)),ROW(_Data!B2:B111)-1),17)),"")} | J25: {=IFERROR(INDEX(_Data!J2:J111,SMALL(IF(ISNUMBER(SEARCH(IF(G4="",CHAR(1),G4),_Data!B2:B111)),ROW(_Data!B2:B111)-1),17)),"")} | K25: {=IFERROR(INDEX(_Data!K2:K111,SMALL(IF(ISNUMBER(SEARCH(IF(G4="",CHAR(1),G4),_Data!B2:B111)),ROW(_Data!B2:B111)-1),17)),"")} | L25: {=IFERROR(INDEX(_Data!L2:L111,SMALL(IF(ISNUMBER(SEARCH(IF(G4="",CHAR(1),G4),_Data!B2:B111)),ROW(_Data!B2:B111)-1),17)),"")} | M25: {=IFERROR(INDEX(_Data!M2:M111,SMALL(IF(ISNUMBER(SEARCH(IF(G4="",CHAR(1),G4),_Data!B2:B111)),ROW(_Data!B2:B111)-1),17)),"")} | N25: {=IFERROR(INDEX(_Data!N2:N111,SMALL(IF(ISNUMBER(SEARCH(IF(G4="",CHAR(1),G4),_Data!B2:B111)),ROW(_Data!B2:B111)-1),17)),"")} | O25: {=IFERROR(INDEX(_Data!O2:O111,SMALL(IF(ISNUMBER(SEARCH(IF(G4="",CHAR(1),G4),_Data!B2:B111)),ROW(_Data!B2:B111)-1),17)),"")}
A26: {=IFERROR(INDEX(_Data!A2:A111,SMALL(IF(ISNUMBER(SEARCH(IF(G4="",CHAR(1),G4),_Data!B2:B111)),ROW(_Data!B2:B111)-1),18)),"")} | B26: {=IFERROR(INDEX(_Data!B2:B111,SMALL(IF(ISNUMBER(SEARCH(IF(G4="",CHAR(1),G4),_Data!B2:B111)),ROW(_Data!B2:B111)-1),18)),"")} | C26: {=IFERROR(INDEX(_Data!C2:C111,SMALL(IF(ISNUMBER(SEARCH(IF(G4="",CHAR(1),G4),_Data!B2:B111)),ROW(_Data!B2:B111)-1),18)),"")} | D26: {=IFERROR(INDEX(_Data!D2:D111,SMALL(IF(ISNUMBER(SEARCH(IF(G4="",CHAR(1),G4),_Data!B2:B111)),ROW(_Data!B2:B111)-1),18)),"")} | E26: {=IFERROR(INDEX(_Data!E2:E111,SMALL(IF(ISNUMBER(SEARCH(IF(G4="",CHAR(1),G4),_Data!B2:B111)),ROW(_Data!B2:B111)-1),18)),"")} | F26: {=IFERROR(INDEX(_Data!F2:F111,SMALL(IF(ISNUMBER(SEARCH(IF(G4="",CHAR(1),G4),_Data!B2:B111)),ROW(_Data!B2:B111)-1),18)),"")} | G26: {=IFERROR(INDEX(_Data!G2:G111,SMALL(IF(ISNUMBER(SEARCH(IF(G4="",CHAR(1),G4),_Data!B2:B111)),ROW(_Data!B2:B111)-1),18)),"")} | H26: {=IFERROR(INDEX(_Data!H2:H111,SMALL(IF(ISNUMBER(SEARCH(IF(G4="",CHAR(1),G4),_Data!B2:B111)),ROW(_Data!B2:B111)-1),18)),"")} | I26: {=IFERROR(INDEX(_Data!I2:I111,SMALL(IF(ISNUMBER(SEARCH(IF(G4="",CHAR(1),G4),_Data!B2:B111)),ROW(_Data!B2:B111)-1),18)),"")} | J26: {=IFERROR(INDEX(_Data!J2:J111,SMALL(IF(ISNUMBER(SEARCH(IF(G4="",CHAR(1),G4),_Data!B2:B111)),ROW(_Data!B2:B111)-1),18)),"")} | K26: {=IFERROR(INDEX(_Data!K2:K111,SMALL(IF(ISNUMBER(SEARCH(IF(G4="",CHAR(1),G4),_Data!B2:B111)),ROW(_Data!B2:B111)-1),18)),"")} | L26: {=IFERROR(INDEX(_Data!L2:L111,SMALL(IF(ISNUMBER(SEARCH(IF(G4="",CHAR(1),G4),_Data!B2:B111)),ROW(_Data!B2:B111)-1),18)),"")} | M26: {=IFERROR(INDEX(_Data!M2:M111,SMALL(IF(ISNUMBER(SEARCH(IF(G4="",CHAR(1),G4),_Data!B2:B111)),ROW(_Data!B2:B111)-1),18)),"")} | N26: {=IFERROR(INDEX(_Data!N2:N111,SMALL(IF(ISNUMBER(SEARCH(IF(G4="",CHAR(1),G4),_Data!B2:B111)),ROW(_Data!B2:B111)-1),18)),"")} | O26: {=IFERROR(INDEX(_Data!O2:O111,SMALL(IF(ISNUMBER(SEARCH(IF(G4="",CHAR(1),G4),_Data!B2:B111)),ROW(_Data!B2:B111)-1),18)),"")}
A27: {=IFERROR(INDEX(_Data!A2:A111,SMALL(IF(ISNUMBER(SEARCH(IF(G4="",CHAR(1),G4),_Data!B2:B111)),ROW(_Data!B2:B111)-1),19)),"")} | B27: {=IFERROR(INDEX(_Data!B2:B111,SMALL(IF(ISNUMBER(SEARCH(IF(G4="",CHAR(1),G4),_Data!B2:B111)),ROW(_Data!B2:B111)-1),19)),"")} | C27: {=IFERROR(INDEX(_Data!C2:C111,SMALL(IF(ISNUMBER(SEARCH(IF(G4="",CHAR(1),G4),_Data!B2:B111)),ROW(_Data!B2:B111)-1),19)),"")} | D27: {=IFERROR(INDEX(_Data!D2:D111,SMALL(IF(ISNUMBER(SEARCH(IF(G4="",CHAR(1),G4),_Data!B2:B111)),ROW(_Data!B2:B111)-1),19)),"")} | E27: {=IFERROR(INDEX(_Data!E2:E111,SMALL(IF(ISNUMBER(SEARCH(IF(G4="",CHAR(1),G4),_Data!B2:B111)),ROW(_Data!B2:B111)-1),19)),"")} | F27: {=IFERROR(INDEX(_Data!F2:F111,SMALL(IF(ISNUMBER(SEARCH(IF(G4="",CHAR(1),G4),_Data!B2:B111)),ROW(_Data!B2:B111)-1),19)),"")} | G27: {=IFERROR(INDEX(_Data!G2:G111,SMALL(IF(ISNUMBER(SEARCH(IF(G4="",CHAR(1),G4),_Data!B2:B111)),ROW(_Data!B2:B111)-1),19)),"")} | H27: {=IFERROR(INDEX(_Data!H2:H111,SMALL(IF(ISNUMBER(SEARCH(IF(G4="",CHAR(1),G4),_Data!B2:B111)),ROW(_Data!B2:B111)-1),19)),"")} | I27: {=IFERROR(INDEX(_Data!I2:I111,SMALL(IF(ISNUMBER(SEARCH(IF(G4="",CHAR(1),G4),_Data!B2:B111)),ROW(_Data!B2:B111)-1),19)),"")} | J27: {=IFERROR(INDEX(_Data!J2:J111,SMALL(IF(ISNUMBER(SEARCH(IF(G4="",CHAR(1),G4),_Data!B2:B111)),ROW(_Data!B2:B111)-1),19)),"")} | K27: {=IFERROR(INDEX(_Data!K2:K111,SMALL(IF(ISNUMBER(SEARCH(IF(G4="",CHAR(1),G4),_Data!B2:B111)),ROW(_Data!B2:B111)-1),19)),"")} | L27: {=IFERROR(INDEX(_Data!L2:L111,SMALL(IF(ISNUMBER(SEARCH(IF(G4="",CHAR(1),G4),_Data!B2:B111)),ROW(_Data!B2:B111)-1),19)),"")} | M27: {=IFERROR(INDEX(_Data!M2:M111,SMALL(IF(ISNUMBER(SEARCH(IF(G4="",CHAR(1),G4),_Data!B2:B111)),ROW(_Data!B2:B111)-1),19)),"")} | N27: {=IFERROR(INDEX(_Data!N2:N111,SMALL(IF(ISNUMBER(SEARCH(IF(G4="",CHAR(1),G4),_Data!B2:B111)),ROW(_Data!B2:B111)-1),19)),"")} | O27: {=IFERROR(INDEX(_Data!O2:O111,SMALL(IF(ISNUMBER(SEARCH(IF(G4="",CHAR(1),G4),_Data!B2:B111)),ROW(_Data!B2:B111)-1),19)),"")}
A28: {=IFERROR(INDEX(_Data!A2:A111,SMALL(IF(ISNUMBER(SEARCH(IF(G4="",CHAR(1),G4),_Data!B2:B111)),ROW(_Data!B2:B111)-1),20)),"")} | B28: {=IFERROR(INDEX(_Data!B2:B111,SMALL(IF(ISNUMBER(SEARCH(IF(G4="",CHAR(1),G4),_Data!B2:B111)),ROW(_Data!B2:B111)-1),20)),"")} | C28: {=IFERROR(INDEX(_Data!C2:C111,SMALL(IF(ISNUMBER(SEARCH(IF(G4="",CHAR(1),G4),_Data!B2:B111)),ROW(_Data!B2:B111)-1),20)),"")} | D28: {=IFERROR(INDEX(_Data!D2:D111,SMALL(IF(ISNUMBER(SEARCH(IF(G4="",CHAR(1),G4),_Data!B2:B111)),ROW(_Data!B2:B111)-1),20)),"")} | E28: {=IFERROR(INDEX(_Data!E2:E111,SMALL(IF(ISNUMBER(SEARCH(IF(G4="",CHAR(1),G4),_Data!B2:B111)),ROW(_Data!B2:B111)-1),20)),"")} | F28: {=IFERROR(INDEX(_Data!F2:F111,SMALL(IF(ISNUMBER(SEARCH(IF(G4="",CHAR(1),G4),_Data!B2:B111)),ROW(_Data!B2:B111)-1),20)),"")} | G28: {=IFERROR(INDEX(_Data!G2:G111,SMALL(IF(ISNUMBER(SEARCH(IF(G4="",CHAR(1),G4),_Data!B2:B111)),ROW(_Data!B2:B111)-1),20)),"")} | H28: {=IFERROR(INDEX(_Data!H2:H111,SMALL(IF(ISNUMBER(SEARCH(IF(G4="",CHAR(1),G4),_Data!B2:B111)),ROW(_Data!B2:B111)-1),20)),"")} | I28: {=IFERROR(INDEX(_Data!I2:I111,SMALL(IF(ISNUMBER(SEARCH(IF(G4="",CHAR(1),G4),_Data!B2:B111)),ROW(_Data!B2:B111)-1),20)),"")} | J28: {=IFERROR(INDEX(_Data!J2:J111,SMALL(IF(ISNUMBER(SEARCH(IF(G4="",CHAR(1),G4),_Data!B2:B111)),ROW(_Data!B2:B111)-1),20)),"")} | K28: {=IFERROR(INDEX(_Data!K2:K111,SMALL(IF(ISNUMBER(SEARCH(IF(G4="",CHAR(1),G4),_Data!B2:B111)),ROW(_Data!B2:B111)-1),20)),"")} | L28: {=IFERROR(INDEX(_Data!L2:L111,SMALL(IF(ISNUMBER(SEARCH(IF(G4="",CHAR(1),G4),_Data!B2:B111)),ROW(_Data!B2:B111)-1),20)),"")} | M28: {=IFERROR(INDEX(_Data!M2:M111,SMALL(IF(ISNUMBER(SEARCH(IF(G4="",CHAR(1),G4),_Data!B2:B111)),ROW(_Data!B2:B111)-1),20)),"")} | N28: {=IFERROR(INDEX(_Data!N2:N111,SMALL(IF(ISNUMBER(SEARCH(IF(G4="",CHAR(1),G4),_Data!B2:B111)),ROW(_Data!B2:B111)-1),20)),"")} | O28: {=IFERROR(INDEX(_Data!O2:O111,SMALL(IF(ISNUMBER(SEARCH(IF(G4="",CHAR(1),G4),_Data!B2:B111)),ROW(_Data!B2:B111)-1),20)),"")}
A30: 📱 Resultados — Telefonía
A31: Usuario | B31: N° Teléfono | C31: Compañía | D31: Equipo | E31: IMEI/ICCID | F31: Observacion | G31: Área
A32: {=IFERROR(INDEX(_Data!Q2:Q60,SMALL(IF(ISNUMBER(SEARCH(IF(G4="",CHAR(1),G4),_Data!Q2:Q60)),ROW(_Data!Q2:Q60)-1),1)),"")} -> Pia Escobar | B32: {=IFERROR(INDEX(_Data!R2:R60,SMALL(IF(ISNUMBER(SEARCH(IF(G4="",CHAR(1),G4),_Data!Q2:Q60)),ROW(_Data!Q2:Q60)-1),1)),"")} -> 56950406230 | C32: {=IFERROR(INDEX(_Data!S2:S60,SMALL(IF(ISNUMBER(SEARCH(IF(G4="",CHAR(1),G4),_Data!Q2:Q60)),ROW(_Data!Q2:Q60)-1),1)),"")} -> Claro | D32: {=IFERROR(INDEX(_Data!T2:T60,SMALL(IF(ISNUMBER(SEARCH(IF(G4="",CHAR(1),G4),_Data!Q2:Q60)),ROW(_Data!Q2:Q60)-1),1)),"")} -> Galaxy A22 | E32: {=IFERROR(INDEX(_Data!U2:U60,SMALL(IF(ISNUMBER(SEARCH(IF(G4="",CHAR(1),G4),_Data!Q2:Q60)),ROW(_Data!Q2:Q60)-1),1)),"")} -> 353325955465822 | F32: {=IFERROR(INDEX(_Data!V2:V60,SMALL(IF(ISNUMBER(SEARCH(IF(G4="",CHAR(1),G4),_Data!Q2:Q60)),ROW(_Data!Q2:Q60)-1),1)),"")} -> Marcelo | G32: {=IFERROR(INDEX(_Data!W2:W60,SMALL(IF(ISNUMBER(SEARCH(IF(G4="",CHAR(1),G4),_Data!Q2:Q60)),ROW(_Data!Q2:Q60)-1),1)),"")} -> Calidad
A33: {=IFERROR(INDEX(_Data!Q2:Q60,SMALL(IF(ISNUMBER(SEARCH(IF(G4="",CHAR(1),G4),_Data!Q2:Q60)),ROW(_Data!Q2:Q60)-1),2)),"")} | B33: {=IFERROR(INDEX(_Data!R2:R60,SMALL(IF(ISNUMBER(SEARCH(IF(G4="",CHAR(1),G4),_Data!Q2:Q60)),ROW(_Data!Q2:Q60)-1),2)),"")} | C33: {=IFERROR(INDEX(_Data!S2:S60,SMALL(IF(ISNUMBER(SEARCH(IF(G4="",CHAR(1),G4),_Data!Q2:Q60)),ROW(_Data!Q2:Q60)-1),2)),"")} | D33: {=IFERROR(INDEX(_Data!T2:T60,SMALL(IF(ISNUMBER(SEARCH(IF(G4="",CHAR(1),G4),_Data!Q2:Q60)),ROW(_Data!Q2:Q60)-1),2)),"")} | E33: {=IFERROR(INDEX(_Data!U2:U60,SMALL(IF(ISNUMBER(SEARCH(IF(G4="",CHAR(1),G4),_Data!Q2:Q60)),ROW(_Data!Q2:Q60)-1),2)),"")} | F33: {=IFERROR(INDEX(_Data!V2:V60,SMALL(IF(ISNUMBER(SEARCH(IF(G4="",CHAR(1),G4),_Data!Q2:Q60)),ROW(_Data!Q2:Q60)-1),2)),"")} | G33: {=IFERROR(INDEX(_Data!W2:W60,SMALL(IF(ISNUMBER(SEARCH(IF(G4="",CHAR(1),G4),_Data!Q2:Q60)),ROW(_Data!Q2:Q60)-1),2)),"")}
A34: {=IFERROR(INDEX(_Data!Q2:Q60,SMALL(IF(ISNUMBER(SEARCH(IF(G4="",CHAR(1),G4),_Data!Q2:Q60)),ROW(_Data!Q2:Q60)-1),3)),"")} | B34: {=IFERROR(INDEX(_Data!R2:R60,SMALL(IF(ISNUMBER(SEARCH(IF(G4="",CHAR(1),G4),_Data!Q2:Q60)),ROW(_Data!Q2:Q60)-1),3)),"")} | C34: {=IFERROR(INDEX(_Data!S2:S60,SMALL(IF(ISNUMBER(SEARCH(IF(G4="",CHAR(1),G4),_Data!Q2:Q60)),ROW(_Data!Q2:Q60)-1),3)),"")} | D34: {=IFERROR(INDEX(_Data!T2:T60,SMALL(IF(ISNUMBER(SEARCH(IF(G4="",CHAR(1),G4),_Data!Q2:Q60)),ROW(_Data!Q2:Q60)-1),3)),"")} | E34: {=IFERROR(INDEX(_Data!U2:U60,SMALL(IF(ISNUMBER(SEARCH(IF(G4="",CHAR(1),G4),_Data!Q2:Q60)),ROW(_Data!Q2:Q60)-1),3)),"")} | F34: {=IFERROR(INDEX(_Data!V2:V60,SMALL(IF(ISNUMBER(SEARCH(IF(G4="",CHAR(1),G4),_Data!Q2:Q60)),ROW(_Data!Q2:Q60)-1),3)),"")} | G34: {=IFERROR(INDEX(_Data!W2:W60,SMALL(IF(ISNUMBER(SEARCH(IF(G4="",CHAR(1),G4),_Data!Q2:Q60)),ROW(_Data!Q2:Q60)-1),3)),"")}
A35: {=IFERROR(INDEX(_Data!Q2:Q60,SMALL(IF(ISNUMBER(SEARCH(IF(G4="",CHAR(1),G4),_Data!Q2:Q60)),ROW(_Data!Q2:Q60)-1),4)),"")} | B35: {=IFERROR(INDEX(_Data!R2:R60,SMALL(IF(ISNUMBER(SEARCH(IF(G4="",CHAR(1),G4),_Data!Q2:Q60)),ROW(_Data!Q2:Q60)-1),4)),"")} | C35: {=IFERROR(INDEX(_Data!S2:S60,SMALL(IF(ISNUMBER(SEARCH(IF(G4="",CHAR(1),G4),_Data!Q2:Q60)),ROW(_Data!Q2:Q60)-1),4)),"")} | D35: {=IFERROR(INDEX(_Data!T2:T60,SMALL(IF(ISNUMBER(SEARCH(IF(G4="",CHAR(1),G4),_Data!Q2:Q60)),ROW(_Data!Q2:Q60)-1),4)),"")} | E35: {=IFERROR(INDEX(_Data!U2:U60,SMALL(IF(ISNUMBER(SEARCH(IF(G4="",CHAR(1),G4),_Data!Q2:Q60)),ROW(_Data!Q2:Q60)-1),4)),"")} | F35: {=IFERROR(INDEX(_Data!V2:V60,SMALL(IF(ISNUMBER(SEARCH(IF(G4="",CHAR(1),G4),_Data!Q2:Q60)),ROW(_Data!Q2:Q60)-1),4)),"")} | G35: {=IFERROR(INDEX(_Data!W2:W60,SMALL(IF(ISNUMBER(SEARCH(IF(G4="",CHAR(1),G4),_Data!Q2:Q60)),ROW(_Data!Q2:Q60)-1),4)),"")}
A36: {=IFERROR(INDEX(_Data!Q2:Q60,SMALL(IF(ISNUMBER(SEARCH(IF(G4="",CHAR(1),G4),_Data!Q2:Q60)),ROW(_Data!Q2:Q60)-1),5)),"")} | B36: {=IFERROR(INDEX(_Data!R2:R60,SMALL(IF(ISNUMBER(SEARCH(IF(G4="",CHAR(1),G4),_Data!Q2:Q60)),ROW(_Data!Q2:Q60)-1),5)),"")} | C36: {=IFERROR(INDEX(_Data!S2:S60,SMALL(IF(ISNUMBER(SEARCH(IF(G4="",CHAR(1),G4),_Data!Q2:Q60)),ROW(_Data!Q2:Q60)-1),5)),"")} | D36: {=IFERROR(INDEX(_Data!T2:T60,SMALL(IF(ISNUMBER(SEARCH(IF(G4="",CHAR(1),G4),_Data!Q2:Q60)),ROW(_Data!Q2:Q60)-1),5)),"")} | E36: {=IFERROR(INDEX(_Data!U2:U60,SMALL(IF(ISNUMBER(SEARCH(IF(G4="",CHAR(1),G4),_Data!Q2:Q60)),ROW(_Data!Q2:Q60)-1),5)),"")} | F36: {=IFERROR(INDEX(_Data!V2:V60,SMALL(IF(ISNUMBER(SEARCH(IF(G4="",CHAR(1),G4),_Data!Q2:Q60)),ROW(_Data!Q2:Q60)-1),5)),"")} | G36: {=IFERROR(INDEX(_Data!W2:W60,SMALL(IF(ISNUMBER(SEARCH(IF(G4="",CHAR(1),G4),_Data!Q2:Q60)),ROW(_Data!Q2:Q60)-1),5)),"")}
A37: {=IFERROR(INDEX(_Data!Q2:Q60,SMALL(IF(ISNUMBER(SEARCH(IF(G4="",CHAR(1),G4),_Data!Q2:Q60)),ROW(_Data!Q2:Q60)-1),6)),"")} | B37: {=IFERROR(INDEX(_Data!R2:R60,SMALL(IF(ISNUMBER(SEARCH(IF(G4="",CHAR(1),G4),_Data!Q2:Q60)),ROW(_Data!Q2:Q60)-1),6)),"")} | C37: {=IFERROR(INDEX(_Data!S2:S60,SMALL(IF(ISNUMBER(SEARCH(IF(G4="",CHAR(1),G4),_Data!Q2:Q60)),ROW(_Data!Q2:Q60)-1),6)),"")} | D37: {=IFERROR(INDEX(_Data!T2:T60,SMALL(IF(ISNUMBER(SEARCH(IF(G4="",CHAR(1),G4),_Data!Q2:Q60)),ROW(_Data!Q2:Q60)-1),6)),"")} | E37: {=IFERROR(INDEX(_Data!U2:U60,SMALL(IF(ISNUMBER(SEARCH(IF(G4="",CHAR(1),G4),_Data!Q2:Q60)),ROW(_Data!Q2:Q60)-1),6)),"")} | F37: {=IFERROR(INDEX(_Data!V2:V60,SMALL(IF(ISNUMBER(SEARCH(IF(G4="",CHAR(1),G4),_Data!Q2:Q60)),ROW(_Data!Q2:Q60)-1),6)),"")} | G37: {=IFERROR(INDEX(_Data!W2:W60,SMALL(IF(ISNUMBER(SEARCH(IF(G4="",CHAR(1),G4),_Data!Q2:Q60)),ROW(_Data!Q2:Q60)-1),6)),"")}
A38: {=IFERROR(INDEX(_Data!Q2:Q60,SMALL(IF(ISNUMBER(SEARCH(IF(G4="",CHAR(1),G4),_Data!Q2:Q60)),ROW(_Data!Q2:Q60)-1),7)),"")} | B38: {=IFERROR(INDEX(_Data!R2:R60,SMALL(IF(ISNUMBER(SEARCH(IF(G4="",CHAR(1),G4),_Data!Q2:Q60)),ROW(_Data!Q2:Q60)-1),7)),"")} | C38: {=IFERROR(INDEX(_Data!S2:S60,SMALL(IF(ISNUMBER(SEARCH(IF(G4="",CHAR(1),G4),_Data!Q2:Q60)),ROW(_Data!Q2:Q60)-1),7)),"")} | D38: {=IFERROR(INDEX(_Data!T2:T60,SMALL(IF(ISNUMBER(SEARCH(IF(G4="",CHAR(1),G4),_Data!Q2:Q60)),ROW(_Data!Q2:Q60)-1),7)),"")} | E38: {=IFERROR(INDEX(_Data!U2:U60,SMALL(IF(ISNUMBER(SEARCH(IF(G4="",CHAR(1),G4),_Data!Q2:Q60)),ROW(_Data!Q2:Q60)-1),7)),"")} | F38: {=IFERROR(INDEX(_Data!V2:V60,SMALL(IF(ISNUMBER(SEARCH(IF(G4="",CHAR(1),G4),_Data!Q2:Q60)),ROW(_Data!Q2:Q60)-1),7)),"")} | G38: {=IFERROR(INDEX(_Data!W2:W60,SMALL(IF(ISNUMBER(SEARCH(IF(G4="",CHAR(1),G4),_Data!Q2:Q60)),ROW(_Data!Q2:Q60)-1),7)),"")}
A39: {=IFERROR(INDEX(_Data!Q2:Q60,SMALL(IF(ISNUMBER(SEARCH(IF(G4="",CHAR(1),G4),_Data!Q2:Q60)),ROW(_Data!Q2:Q60)-1),8)),"")} | B39: {=IFERROR(INDEX(_Data!R2:R60,SMALL(IF(ISNUMBER(SEARCH(IF(G4="",CHAR(1),G4),_Data!Q2:Q60)),ROW(_Data!Q2:Q60)-1),8)),"")} | C39: {=IFERROR(INDEX(_Data!S2:S60,SMALL(IF(ISNUMBER(SEARCH(IF(G4="",CHAR(1),G4),_Data!Q2:Q60)),ROW(_Data!Q2:Q60)-1),8)),"")} | D39: {=IFERROR(INDEX(_Data!T2:T60,SMALL(IF(ISNUMBER(SEARCH(IF(G4="",CHAR(1),G4),_Data!Q2:Q60)),ROW(_Data!Q2:Q60)-1),8)),"")} | E39: {=IFERROR(INDEX(_Data!U2:U60,SMALL(IF(ISNUMBER(SEARCH(IF(G4="",CHAR(1),G4),_Data!Q2:Q60)),ROW(_Data!Q2:Q60)-1),8)),"")} | F39: {=IFERROR(INDEX(_Data!V2:V60,SMALL(IF(ISNUMBER(SEARCH(IF(G4="",CHAR(1),G4),_Data!Q2:Q60)),ROW(_Data!Q2:Q60)-1),8)),"")} | G39: {=IFERROR(INDEX(_Data!W2:W60,SMALL(IF(ISNUMBER(SEARCH(IF(G4="",CHAR(1),G4),_Data!Q2:Q60)),ROW(_Data!Q2:Q60)-1),8)),"")}
A40: {=IFERROR(INDEX(_Data!Q2:Q60,SMALL(IF(ISNUMBER(SEARCH(IF(G4="",CHAR(1),G4),_Data!Q2:Q60)),ROW(_Data!Q2:Q60)-1),9)),"")} | B40: {=IFERROR(INDEX(_Data!R2:R60,SMALL(IF(ISNUMBER(SEARCH(IF(G4="",CHAR(1),G4),_Data!Q2:Q60)),ROW(_Data!Q2:Q60)-1),9)),"")} | C40: {=IFERROR(INDEX(_Data!S2:S60,SMALL(IF(ISNUMBER(SEARCH(IF(G4="",CHAR(1),G4),_Data!Q2:Q60)),ROW(_Data!Q2:Q60)-1),9)),"")} | D40: {=IFERROR(INDEX(_Data!T2:T60,SMALL(IF(ISNUMBER(SEARCH(IF(G4="",CHAR(1),G4),_Data!Q2:Q60)),ROW(_Data!Q2:Q60)-1),9)),"")} | E40: {=IFERROR(INDEX(_Data!U2:U60,SMALL(IF(ISNUMBER(SEARCH(IF(G4="",CHAR(1),G4),_Data!Q2:Q60)),ROW(_Data!Q2:Q60)-1),9)),"")} | F40: {=IFERROR(INDEX(_Data!V2:V60,SMALL(IF(ISNUMBER(SEARCH(IF(G4="",CHAR(1),G4),_Data!Q2:Q60)),ROW(_Data!Q2:Q60)-1),9)),"")} | G40: {=IFERROR(INDEX(_Data!W2:W60,SMALL(IF(ISNUMBER(SEARCH(IF(G4="",CHAR(1),G4),_Data!Q2:Q60)),ROW(_Data!Q2:Q60)-1),9)),"")}
A41: {=IFERROR(INDEX(_Data!Q2:Q60,SMALL(IF(ISNUMBER(SEARCH(IF(G4="",CHAR(1),G4),_Data!Q2:Q60)),ROW(_Data!Q2:Q60)-1),10)),"")} | B41: {=IFERROR(INDEX(_Data!R2:R60,SMALL(IF(ISNUMBER(SEARCH(IF(G4="",CHAR(1),G4),_Data!Q2:Q60)),ROW(_Data!Q2:Q60)-1),10)),"")} | C41: {=IFERROR(INDEX(_Data!S2:S60,SMALL(IF(ISNUMBER(SEARCH(IF(G4="",CHAR(1),G4),_Data!Q2:Q60)),ROW(_Data!Q2:Q60)-1),10)),"")} | D41: {=IFERROR(INDEX(_Data!T2:T60,SMALL(IF(ISNUMBER(SEARCH(IF(G4="",CHAR(1),G4),_Data!Q2:Q60)),ROW(_Data!Q2:Q60)-1),10)),"")} | E41: {=IFERROR(INDEX(_Data!U2:U60,SMALL(IF(ISNUMBER(SEARCH(IF(G4="",CHAR(1),G4),_Data!Q2:Q60)),ROW(_Data!Q2:Q60)-1),10)),"")} | F41: {=IFERROR(INDEX(_Data!V2:V60,SMALL(IF(ISNUMBER(SEARCH(IF(G4="",CHAR(1),G4),_Data!Q2:Q60)),ROW(_Data!Q2:Q60)-1),10)),"")} | G41: {=IFERROR(INDEX(_Data!W2:W60,SMALL(IF(ISNUMBER(SEARCH(IF(G4="",CHAR(1),G4),_Data!Q2:Q60)),ROW(_Data!Q2:Q60)-1),10)),"")}
A42: {=IFERROR(INDEX(_Data!Q2:Q60,SMALL(IF(ISNUMBER(SEARCH(IF(G4="",CHAR(1),G4),_Data!Q2:Q60)),ROW(_Data!Q2:Q60)-1),11)),"")} | B42: {=IFERROR(INDEX(_Data!R2:R60,SMALL(IF(ISNUMBER(SEARCH(IF(G4="",CHAR(1),G4),_Data!Q2:Q60)),ROW(_Data!Q2:Q60)-1),11)),"")} | C42: {=IFERROR(INDEX(_Data!S2:S60,SMALL(IF(ISNUMBER(SEARCH(IF(G4="",CHAR(1),G4),_Data!Q2:Q60)),ROW(_Data!Q2:Q60)-1),11)),"")} | D42: {=IFERROR(INDEX(_Data!T2:T60,SMALL(IF(ISNUMBER(SEARCH(IF(G4="",CHAR(1),G4),_Data!Q2:Q60)),ROW(_Data!Q2:Q60)-1),11)),"")} | E42: {=IFERROR(INDEX(_Data!U2:U60,SMALL(IF(ISNUMBER(SEARCH(IF(G4="",CHAR(1),G4),_Data!Q2:Q60)),ROW(_Data!Q2:Q60)-1),11)),"")} | F42: {=IFERROR(INDEX(_Data!V2:V60,SMALL(IF(ISNUMBER(SEARCH(IF(G4="",CHAR(1),G4),_Data!Q2:Q60)),ROW(_Data!Q2:Q60)-1),11)),"")} | G42: {=IFERROR(INDEX(_Data!W2:W60,SMALL(IF(ISNUMBER(SEARCH(IF(G4="",CHAR(1),G4),_Data!Q2:Q60)),ROW(_Data!Q2:Q60)-1),11)),"")}
A43: {=IFERROR(INDEX(_Data!Q2:Q60,SMALL(IF(ISNUMBER(SEARCH(IF(G4="",CHAR(1),G4),_Data!Q2:Q60)),ROW(_Data!Q2:Q60)-1),12)),"")} | B43: {=IFERROR(INDEX(_Data!R2:R60,SMALL(IF(ISNUMBER(SEARCH(IF(G4="",CHAR(1),G4),_Data!Q2:Q60)),ROW(_Data!Q2:Q60)-1),12)),"")} | C43: {=IFERROR(INDEX(_Data!S2:S60,SMALL(IF(ISNUMBER(SEARCH(IF(G4="",CHAR(1),G4),_Data!Q2:Q60)),ROW(_Data!Q2:Q60)-1),12)),"")} | D43: {=IFERROR(INDEX(_Data!T2:T60,SMALL(IF(ISNUMBER(SEARCH(IF(G4="",CHAR(1),G4),_Data!Q2:Q60)),ROW(_Data!Q2:Q60)-1),12)),"")} | E43: {=IFERROR(INDEX(_Data!U2:U60,SMALL(IF(ISNUMBER(SEARCH(IF(G4="",CHAR(1),G4),_Data!Q2:Q60)),ROW(_Data!Q2:Q60)-1),12)),"")} | F43: {=IFERROR(INDEX(_Data!V2:V60,SMALL(IF(ISNUMBER(SEARCH(IF(G4="",CHAR(1),G4),_Data!Q2:Q60)),ROW(_Data!Q2:Q60)-1),12)),"")} | G43: {=IFERROR(INDEX(_Data!W2:W60,SMALL(IF(ISNUMBER(SEARCH(IF(G4="",CHAR(1),G4),_Data!Q2:Q60)),ROW(_Data!Q2:Q60)-1),12)),"")}
A44: {=IFERROR(INDEX(_Data!Q2:Q60,SMALL(IF(ISNUMBER(SEARCH(IF(G4="",CHAR(1),G4),_Data!Q2:Q60)),ROW(_Data!Q2:Q60)-1),13)),"")} | B44: {=IFERROR(INDEX(_Data!R2:R60,SMALL(IF(ISNUMBER(SEARCH(IF(G4="",CHAR(1),G4),_Data!Q2:Q60)),ROW(_Data!Q2:Q60)-1),13)),"")} | C44: {=IFERROR(INDEX(_Data!S2:S60,SMALL(IF(ISNUMBER(SEARCH(IF(G4="",CHAR(1),G4),_Data!Q2:Q60)),ROW(_Data!Q2:Q60)-1),13)),"")} | D44: {=IFERROR(INDEX(_Data!T2:T60,SMALL(IF(ISNUMBER(SEARCH(IF(G4="",CHAR(1),G4),_Data!Q2:Q60)),ROW(_Data!Q2:Q60)-1),13)),"")} | E44: {=IFERROR(INDEX(_Data!U2:U60,SMALL(IF(ISNUMBER(SEARCH(IF(G4="",CHAR(1),G4),_Data!Q2:Q60)),ROW(_Data!Q2:Q60)-1),13)),"")} | F44: {=IFERROR(INDEX(_Data!V2:V60,SMALL(IF(ISNUMBER(SEARCH(IF(G4="",CHAR(1),G4),_Data!Q2:Q60)),ROW(_Data!Q2:Q60)-1),13)),"")} | G44: {=IFERROR(INDEX(_Data!W2:W60,SMALL(IF(ISNUMBER(SEARCH(IF(G4="",CHAR(1),G4),_Data!Q2:Q60)),ROW(_Data!Q2:Q60)-1),13)),"")}
...

Sheet Telefonía
A1: 📱 INVENTARIO TELEFONÍA
A2: Usuario | B2: N° Teléfono | C2: Compañía | D2: Equipo | E2: IMEI/ICCID | F2: Observacion | G2: Área
A3: Giselle Rosales | B3: 56941127502 | C3: Claro | D3: Samsung Galaxy A22 | E3: 353325955457688 | G3: Finanzas
A4: Patricia Bustos | B4: 56996407624 | C4: Claro | D4: Motorola E13 | E4: 357521205244183 | G4: RRHH
A5: Nicole Torres | B5: 56950000761 | C5: Claro | D5: Iphone 11 | E5: 356811119825230 | G5: RRHH
A6: Jean Paul | B6: 56947081292 | C6: Claro | D6: Celular propio | E6: 356532963895810 | G6: MKT
A7: Leonel Rojas | B7: 56968490485 | C7: Claro | D7: Samsung Galaxy A22 | E7: 353325956071207 | G7: Zonal
A8: Chanel Salazar | B8: 56941130516 | C8: Claro | D8: Samsung Galaxy A22 | E8: 353325955453810 | G8: Gerente local
A9: Capacitacion | B9: 56964958620 | C9: Claro | F9: Ex Evelyn Barrera/ No tiene buzon de voz ni wsp
A10: Rodrigo Garcia | B10: 56963346017 | C10: Claro | F10: Ex Erick Giraldo/ se llamó y no contestó. No tiene wsp
A11: Andrea Parisca | B11: 56993430683 | C11: Claro | D11: Celular propio | F11: Celular no detecta ICCID de la sim | G11: Call center
A12: Cristian Parada | B12: 56991608483 | C12: Claro | D12: Samsung Galaxy A14 | E12: 35054264592800 | G12: Prevencion de riesgos
A13: Mariangela Aranguren | B13: 56963346093 | C13: Claro | D13: Motorola E13 | E13: 357521205245305 | G13: Compras
A14: Jefran Valecillos | B14: 56968422358 | C14: Claro | D14: Celular propio | G14: Gerente operaciones
A15: Marcela Lillo | B15: 56950000373 | C15: Claro | D15: Motorola G05 | E15: 359488352152643 | F15: Ex Nicole Echeverria | G15: MKT
A16: Nicolas Moya | B16: 56950000772 | C16: Claro | D16: Celular propio | E16: 8956030215875618816 | G16: Informatica
A17: Melissa Cunza | B17: 56990234718 | C17: Claro | D17: Iphone 11 | E17: 351174770524955 | G17: Gerenta RRHH
A18: Ricardo San Martin | B18: 56976560604 | C18: Claro | D18: Iphone XR | E18: DX3FJ828KXK1 | G18: Auditoria
A19: Patricio Castillo | B19: 56976560560 | C19: Claro | D19: Celular propio | E19: 359358947490669 | G19: Mantencion
A20: Juan Carlos Varea | B20: 56964958619 | C20: Claro | D20: Motorola G35 256G | E20: 356304136221963 | F20: Ex colaborador | G20: Mantencion
A21: Aracely Aviles | B21: 56981644643 | C21: Claro | D21: Iphone XR (roto), pero usa personal | E21: 8956034253031710720 | G21: Commissary
A22: Magdalena Soldati | B22: 56992298821 | C22: Claro | F22: Permiso administrativo | G22: MKT
A23: Matias Sandoval | B23: 56956420464 | C23: Claro | D23: Motorola G35 256GB | E23: 356304136333479 | G23: Informatica
A24: Camila Najle | B24: 56956395706 | C24: Claro | D24: Samsung Galaxy A14 | E24: 35054264569055 | G24: Calidad
A25: Darwin Flores | B25: 56968750172 | C25: Claro | D25: Galaxy A14 | E25: 352054264573511 | G25: MKT
A26: Emilio Droguett | B26: 56981645436 | C26: Claro | D26: Motorola G35 256GB | E26: 353200652142307 | G26: informatica
A27: Trinidad Garcia | B27: 56990234727 | C27: Claro | D27: Galaxy A22 | E27: 352225955462126 | G27: Gerenta Finanzas
A28: German Echesuri | B28: 56964322186 | C28: Claro | D28: Celular propio | E28: 353400795934830 | G28: Control de Gestion
A29: Yexy Oliva | B29: 56983325804 | C29: Claro | D29: Motorola G35 | E29: 356304137088379 | G29: Commissary
A30: Marlon Ferrada | B30: 56946470632 | C30: Claro | D30: Galaxy A14 | E30: 352054264570947 | G30: MKT
A31: Andrea Hidalgo | B31: 56946382799 | C31: Claro | D31: Galaxy A32 | E31: 350257391768688 | G31: Informatica
A32: Paulina Rozas | B32: 56950021464 | C32: Claro | D32: Celular propio | G32: Call center
A33: SAC | B33: 56978977656 | C33: Claro | F33: Paulina/empresa externa | G33: Call center
A34: Valparaiso | B34: 56954522837 | C34: Claro | D34: FEXT | E34: 356369480503027 | F34: Ex Katherine Atias
A35: Roberto Loyola | B35: 56934598991 | C35: Claro | D35: Celular Propio | E35: 8956030234956249088 | G35: Informatica
A36: Roberto Lagos | B36: 56986019701 | C36: Claro | D36: Samsung Galaxy A14 | E36: 352054264581787 | G36: Informatica
A37: Elizabeth Palacios | B37: 56986019865 | C37: Claro | D37: Galaxy A14 | E37: 355709312542456 | G37: Calidad ??
A38: Alejandro Rodriguez | B38: 56986019639 | C38: Claro | D38: Galaxy A14 | E38: 352054263130701 | F38: Ex Jefferson Dornelles | G38: Mantencion
A39: Leonardo Gonzalez | B39: 56946223422 | C39: Claro | F39: No tiene wsp
A40: Camilo Cotal | B40: 56950997436 | C40: Claro | D40: Galaxy A14 | E40: 355709314624153 | G40: Commissary
...

Sheet PC
A1: 💻 INVENTARIO PC
A2: Rut | B2: Persona | C2: Fecha Entrega | D2: Estado | E2: Área | F2: Ubicación | G2: Marca | H2: Modelo | I2: Nº de Serie | J2: Documento Firmado | K2: Mochila | L2: Cargador | M2: Entrega Informática | N2: Entrega al usuario | O2: Observaciones
A3: 20303787-2 | B3: Tiare Sandoval | C3: 12-09-2025 | D3: Asignado | E3: Operaciones | F3: Mall Concepción | G3: Lenovo | H3: IdeaPad Slim3 | I3: PF4CC5M7 | J3: SI | K3: SI | L3: SI | M3: Matias Sandoval | N3: Jefran Valecillos
A4: 14106954-3 | B4: Ana María Galleguillos | C4: 01-09-2025 | D4: Asignado | E4: Operaciones | F4: Manuel Montt | G4: ASUS | H4: Vivobook X515JAB | I4: s1N0CV02141028 | J4: SI | K4: SI | L4: SI | M4: Leopoldo Farr | N4: Jefran Valecillos | O4: Precio 13UF
A5: 18023209-5 | B5: Matías Acuña | C5: 01-07-2025 | D5: Asignado | E5: Marketing | F5: Casa Matriz | G5: ASUS | H5: Vivobook X515JAB | I5: N2N0CX05R26906F | J5: SI | K5: NO | L5: SI | M5: Leopoldo Farr | N5: Magdalena Soldati
A6: 33689249-k | B6: José Daniel Suárez | C6: 15-05-2025 | D6: Asignado | E6: Operaciones | F6: Santa Ana | G6: ASUS | H6: Vivobook Go 14 | I6: S1N0CV02X10802A | J6: SI | K6: SI | L6: SI | M6: Leopoldo Farr | N6: Jefran Valecillos
A7: 22184692-3 | B7: Belén Bernales | C7: 06-01-2025 | D7: Asignado | E7: Administración y Finanzas | F7: Casa Matriz | G7: ASUS | H7: Vivobook Go 14 | I7: S1N0CV02X155026 | J7: SI | K7: NO | L7: SI | M7: Leopoldo Farr | N7: Blanca Marambio
A8: 17923095-k | B8: Patricio Ramos | C8: 28-05-2024 | D8: Asignado | E8: Operaciones | F8: Punta ARenas | G8: ASUS | H8: Vivobook E1404G | I8: S1N0CV02X18302C | J8: SI | K8: NO | L8: SI | M8: Leopoldo Farr | N8: Jefran Valecillos
A9: 18250292-8 | B9: Roberto Lagos | C9: 02-04-2025 | D9: Asignado | E9: Informatica | F9: Casa Matriz | G9: ASUS | H9: Vivobook | I9: R7N0CV03379527C | J9: SI | K9: NO | L9: SI | M9: Leopoldo Farr | N9: Leopoldo Farr
A10: 25433283-6 | B10: Mariuxi Mosquera | C10: 19-07-2024 | D10: Asignado | E10: Operaciones | F10: San Francisco | G10: ASUS | H10: Vivobook | I10: S1N0CV02213020 | J10: SI | K10: NO | L10: SI | M10: Leopoldo Farr | N10: Nehormalin Vargas
A11: 25403967-5 | B11: Nehormarlín Vargas | C11: 01-12-2023 | D11: Asignado | E11: Marketing | F11: Casa Matriz | G11: Dell | H11: Vostro 14 3000 | I11: 5Z278F3 | J11: SI | K11: NO | L11: SI | M11: Leopoldo Farr | N11: Magdalena Soldati
A12: 25978475-1 | B12: Gabriel Casanova | C12: 07-01-2025 | D12: Asignado | E12: Operaciones | F12: Casa Matriz | G12: ASUS | H12: Vivobook Go | I12: X1N0V02X225029 | J12: SI | K12: NO | L12: SI | M12: Leopoldo Farr | N12: Jefran Valecillos
A13: 19211814-k | B13: Giselle Rosales | C13: 19-01-2024 | D13: Asignado | E13: Administración y Finanzas | F13: Casa Matriz | G13: HP | H13: Probook RTL8852AE | I13: 4S055LT#ABM | J13: SI | K13: NO | L13: SI | M13: Leopoldo Farr | N13: Trinidad Garcia | O13: Con adaptador de red
A14: 26738496-7 | B14: Escarlin López | C14: 08-05-2024 | D14: Asignado | E14: Operaciones | F14: Arica | G14: Lenovo | H14: Thinkpad L14 | I14: JVHFC1 | J14: SI | K14: SI | L14: SI | M14: Leopoldo Farr | N14: Jefran Valecillos
A15: 13706170-8 | B15: Aracely Avilés | C15: 29-05-2023 | D15: Asignado | E15: Compras | F15: Casa Matriz | G15: HP | H15: 240 G8 | I15: 8-NTHP5116 | J15: SI | K15: NO | L15: SI | M15: Leopoldo Farr | N15: Leopoldo Farr | O15: confirmar n serie
A16: 10092205-3 | B16: Patricia Bustos | C16: 29-05-2023 | D16: Asignado | E16: RRHH | F16: Casa Matriz | G16: HP | H16: 240 G8 | I16: 8-NTHP5116 | J16: SI | K16: NO | L16: SI | M16: Leopoldo Farr | N16: Leopoldo Farr | O16: Confirmar N serie
A17: 26401374-7 | B17: Gabriel Colls | C17: 16-05-2023 | D17: Asignado | E17: RRHH | F17: Casa Matriz | G17: Lenovo | H17: Thinkpad L14 | I17: R17ET34W | J17: SI | K17: NO | L17: SI | M17: Leopoldo Farr | N17: Leopoldo Farr
